{
  "version": 8,
  "blockIdVersion": 11,
  "anchorX": 0,
  "anchorY": 0,
  "anchorZ": 0,
  "blocks": [
    {
      "x": -24,
      "y": 0,
      "z": -18,
      "name": "Plant_Grass_Sharp_Short"
    },
    {
      "x": -24,
      "y": 0,
      "z": -10,
      "name": "Plant_Grass_Sharp"
    },
    {
      "x": -24,
      "y": 0,
      "z": -9,
      "name": "Plant_Grass_Sharp"
    },
    {
      "x": -24,
      "y": 0,
      "z": -6,
      "name": "Plant_Bush_Green"
    },
    {
      "x": -24,
      "y": 0,
      "z": -2,
      "name": "Plant_Grass_Lush_Short"
    },
    {
      "x": -24,
      "y": 0,
      "z": 2,
      "name": "Plant_Grass_Lush_Short"
    },
    {
      "x": -24,
      "y": 0,
      "z": 3,
      "name": "Plant_Grass_Lush_Short"
    },
    {
      "x": -24,
      "y": 0,
      "z": 7,
      "name": "Plant_Grass_Sharp_Short"
    },
    {
      "x": -24,
      "y": 0,
      "z": 8,
      "name": "*Plant_Crop_Berry_Block_State_Definitions_StageFinal"
    },
    {
      "x": -24,
      "y": 0,
      "z": 9,
      "name": "Plant_Bush"
    },
    {
      "x": -24,
      "y": 0,
      "z": 10,
      "name": "Plant_Bush"
    },
    {
      "x": -24,
      "y": 0,
      "z": 13,
      "name": "Plant_Grass_Sharp"
    },
    {
      "x": -24,
      "y": 0,
      "z": 14,
      "name": "Plant_Grass_Sharp"
    },
    {
      "x": -24,
      "y": 0,
      "z": 15,
      "name": "Plant_Grass_Sharp"
    },
    {
      "x": -24,
      "y": 0,
      "z": 16,
      "name": "Plant_Grass_Sharp_Wild"
    },
    {
      "x": -24,
      "y": 0,
      "z": 17,
      "name": "Plant_Grass_Sharp"
    },
    {
      "x": -23,
      "y": 0,
      "z": -17,
      "name": "Plant_Grass_Lush_Short"
    },
    {
      "x": -23,
      "y": 0,
      "z": -16,
      "name": "Plant_Grass_Lush_Short"
    },
    {
      "x": -23,
      "y": 0,
      "z": -13,
      "name": "Plant_Grass_Sharp"
    },
    {
      "x": -23,
      "y": 0,
      "z": -12,
      "name": "Plant_Grass_Sharp_Wild"
    },
    {
      "x": -23,
      "y": 0,
      "z": -11,
      "name": "Plant_Grass_Sharp_Wild"
    },
    {
      "x": -23,
      "y": 0,
      "z": -10,
      "name": "Plant_Grass_Sharp_Wild"
    },
    {
      "x": -23,
      "y": 0,
      "z": -9,
      "name": "Plant_Grass_Sharp"
    },
    {
      "x": -23,
      "y": 0,
      "z": -7,
      "name": "Plant_Bush_Green"
    },
    {
      "x": -23,
      "y": 0,
      "z": -5,
      "name": "Plant_Bush_Green"
    },
    {
      "x": -23,
      "y": 0,
      "z": -2,
      "name": "Plant_Grass_Sharp_Short"
    },
    {
      "x": -23,
      "y": 0,
      "z": 0,
      "name": "Plant_Grass_Lush_Short"
    },
    {
      "x": -23,
      "y": 0,
      "z": 2,
      "name": "Plant_Grass_Sharp"
    },
    {
      "x": -23,
      "y": 0,
      "z": 3,
      "name": "Plant_Grass_Sharp_Short"
    },
    {
      "x": -23,
      "y": 0,
      "z": 5,
      "name": "Plant_Grass_Lush_Short"
    },
    {
      "x": -23,
      "y": 0,
      "z": 7,
      "name": "Plant_Grass_Sharp"
    },
    {
      "x": -23,
      "y": 0,
      "z": 8,
      "name": "Plant_Bush"
    },
    {
      "x": -23,
      "y": 0,
      "z": 9,
      "name": "Plant_Bush"
    },
    {
      "x": -23,
      "y": 0,
      "z": 11,
      "name": "Plant_Bush"
    },
    {
      "x": -23,
      "y": 0,
      "z": 14,
      "name": "Plant_Grass_Sharp"
    },
    {
      "x": -23,
      "y": 0,
      "z": 15,
      "name": "Plant_Grass_Sharp"
    },
    {
      "x": -23,
      "y": 0,
      "z": 16,
      "name": "Plant_Grass_Sharp_Tall"
    },
    {
      "x": -23,
      "y": 0,
      "z": 17,
      "name": "Plant_Grass_Sharp"
    },
    {
      "x": -22,
      "y": 0,
      "z": -17,
      "name": "Plant_Grass_Lush_Short"
    },
    {
      "x": -22,
      "y": 0,
      "z": -13,
      "name": "Plant_Grass_Sharp"
    },
    {
      "x": -22,
      "y": 0,
      "z": -12,
      "name": "Plant_Grass_Sharp"
    },
    {
      "x": -22,
      "y": 0,
      "z": -11,
      "name": "Plant_Grass_Sharp_Tall"
    },
    {
      "x": -22,
      "y": 0,
      "z": -10,
      "name": "Plant_Grass_Sharp"
    },
    {
      "x": -22,
      "y": 0,
      "z": -9,
      "name": "Plant_Grass_Sharp_Tall"
    },
    {
      "x": -22,
      "y": 0,
      "z": -7,
      "name": "*Plant_Crop_Berry_Block_State_Definitions_StageFinal"
    },
    {
      "x": -22,
      "y": 0,
      "z": -2,
      "name": "Plant_Grass_Sharp_Short"
    },
    {
      "x": -22,
      "y": 3,
      "z": -1,
      "name": "Survival_Trap_Spike_Wood",
      "rotation": 7
    },
    {
      "x": -22,
      "y": 5,
      "z": -1,
      "name": "Survival_Trap_Spike_Wood",
      "rotation": 7
    },
    {
      "x": -22,
      "y": 7,
      "z": -1,
      "name": "Survival_Trap_Spike_Wood",
      "rotation": 7
    },
    {
      "x": -22,
      "y": 0,
      "z": 0,
      "name": "Rock_Stone_Cobble"
    },
    {
      "x": -22,
      "y": 1,
      "z": 0,
      "name": "Rock_Stone_Cobble"
    },
    {
      "x": -22,
      "y": 3,
      "z": 0,
      "name": "Deco_Bone_Ribs_Long",
      "rotation": 5
    },
    {
      "x": -22,
      "y": 7,
      "z": 0,
      "name": "Deco_Bone_Ribs",
      "rotation": 3
    },
    {
      "x": -22,
      "y": 0,
      "z": 1,
      "name": "Rock_Stone_Cobble"
    },
    {
      "x": -22,
      "y": 1,
      "z": 1,
      "name": "Rock_Stone_Cobble"
    },
    {
      "x": -22,
      "y": 5,
      "z": 1,
      "name": "Deco_Bone_Ribs_Long",
      "rotation": 5
    },
    {
      "x": -22,
      "y": 9,
      "z": 1,
      "name": "Deco_Bone_Ribs_Long",
      "rotation": 5
    },
    {
      "x": -22,
      "y": 0,
      "z": 2,
      "name": "Plant_Grass_Lush_Short"
    },
    {
      "x": -22,
      "y": 3,
      "z": 2,
      "name": "Survival_Trap_Spike_Wood",
      "rotation": 7
    },
    {
      "x": -22,
      "y": 5,
      "z": 2,
      "name": "Survival_Trap_Spike_Wood",
      "rotation": 7
    },
    {
      "x": -22,
      "y": 7,
      "z": 2,
      "name": "Survival_Trap_Spike_Wood",
      "rotation": 7
    },
    {
      "x": -22,
      "y": 0,
      "z": 5,
      "name": "Plant_Grass_Sharp"
    },
    {
      "x": -22,
      "y": 0,
      "z": 6,
      "name": "Plant_Grass_Sharp_Short"
    },
    {
      "x": -22,
      "y": 0,
      "z": 7,
      "name": "Plant_Bush"
    },
    {
      "x": -22,
      "y": 0,
      "z": 8,
      "name": "Plant_Grass_Lush_Short"
    },
    {
      "x": -22,
      "y": 0,
      "z": 9,
      "name": "Plant_Bush"
    },
    {
      "x": -22,
      "y": 0,
      "z": 10,
      "name": "Plant_Bush"
    },
    {
      "x": -22,
      "y": 0,
      "z": 11,
      "name": "Plant_Bush"
    },
    {
      "x": -22,
      "y": 0,
      "z": 15,
      "name": "Plant_Grass_Sharp_Tall"
    },
    {
      "x": -22,
      "y": 0,
      "z": 16,
      "name": "Plant_Grass_Sharp"
    },
    {
      "x": -22,
      "y": 0,
      "z": 17,
      "name": "Plant_Grass_Sharp"
    },
    {
      "x": -21,
      "y": 0,
      "z": -13,
      "name": "Plant_Grass_Sharp"
    },
    {
      "x": -21,
      "y": 0,
      "z": -12,
      "name": "Plant_Grass_Sharp_Tall"
    },
    {
      "x": -21,
      "y": 0,
      "z": -11,
      "name": "Plant_Grass_Sharp_Tall"
    },
    {
      "x": -21,
      "y": 0,
      "z": -10,
      "name": "Plant_Grass_Sharp_Tall"
    },
    {
      "x": -21,
      "y": 0,
      "z": -9,
      "name": "Plant_Grass_Sharp"
    },
    {
      "x": -21,
      "y": 0,
      "z": -8,
      "name": "Plant_Grass_Sharp"
    },
    {
      "x": -21,
      "y": 0,
      "z": -7,
      "name": "Plant_Grass_Sharp"
    },
    {
      "x": -21,
      "y": 0,
      "z": -6,
      "name": "Plant_Grass_Sharp_Short"
    },
    {
      "x": -21,
      "y": 0,
      "z": -4,
      "name": "Plant_Bush_Green"
    },
    {
      "x": -21,
      "y": 2,
      "z": -2,
      "name": "Survival_Trap_Spike_Wood",
      "rotation": 6
    },
    {
      "x": -21,
      "y": 4,
      "z": -2,
      "name": "Survival_Trap_Spike_Wood",
      "rotation": 6
    },
    {
      "x": -21,
      "y": 6,
      "z": -2,
      "name": "Survival_Trap_Spike_Wood",
      "rotation": 6
    },
    {
      "x": -21,
      "y": 8,
      "z": -2,
      "name": "Survival_Trap_Spike_Wood",
      "rotation": 6
    },
    {
      "x": -21,
      "y": 0,
      "z": -1,
      "name": "Rock_Stone_Cobble"
    },
    {
      "x": -21,
      "y": 1,
      "z": -1,
      "name": "Rock_Stone_Cobble"
    },
    {
      "x": -21,
      "y": 2,
      "z": -1,
      "name": "Wood_Oak_Trunk",
      "support": 15
    },
    {
      "x": -21,
      "y": 3,
      "z": -1,
      "name": "Wood_Oak_Trunk",
      "support": 15
    },
    {
      "x": -21,
      "y": 4,
      "z": -1,
      "name": "Wood_Oak_Trunk",
      "support": 15
    },
    {
      "x": -21,
      "y": 5,
      "z": -1,
      "name": "Wood_Oak_Trunk",
      "support": 15
    },
    {
      "x": -21,
      "y": 6,
      "z": -1,
      "name": "Wood_Oak_Trunk",
      "support": 15
    },
    {
      "x": -21,
      "y": 7,
      "z": -1,
      "name": "Wood_Oak_Trunk",
      "support": 15
    },
    {
      "x": -21,
      "y": 8,
      "z": -1,
      "name": "Wood_Oak_Trunk",
      "support": 15
    },
    {
      "x": -21,
      "y": 1,
      "z": 0,
      "name": "Rock_Stone_Cobble"
    },
    {
      "x": -21,
      "y": 2,
      "z": 0,
      "name": "Rock_Stone_Cobble"
    },
    {
      "x": -21,
      "y": 3,
      "z": 0,
      "name": "Rock_Stone_Cobble"
    },
    {
      "x": -21,
      "y": 4,
      "z": 0,
      "name": "Rock_Stone_Cobble"
    },
    {
      "x": -21,
      "y": 5,
      "z": 0,
      "name": "Rock_Stone_Cobble"
    },
    {
      "x": -21,
      "y": 6,
      "z": 0,
      "name": "Rock_Stone_Cobble"
    },
    {
      "x": -21,
      "y": 7,
      "z": 0,
      "name": "Rock_Stone_Cobble"
    },
    {
      "x": -21,
      "y": 8,
      "z": 0,
      "name": "Rock_Stone_Cobble"
    },
    {
      "x": -21,
      "y": 9,
      "z": 0,
      "name": "Rock_Stone_Cobble"
    },
    {
      "x": -21,
      "y": 1,
      "z": 1,
      "name": "Rock_Stone_Cobble"
    },
    {
      "x": -21,
      "y": 2,
      "z": 1,
      "name": "Rock_Stone_Cobble"
    },
    {
      "x": -21,
      "y": 3,
      "z": 1,
      "name": "Rock_Stone_Cobble"
    },
    {
      "x": -21,
      "y": 4,
      "z": 1,
      "name": "Rock_Stone_Cobble"
    },
    {
      "x": -21,
      "y": 5,
      "z": 1,
      "name": "Rock_Stone_Cobble"
    },
    {
      "x": -21,
      "y": 6,
      "z": 1,
      "name": "Rock_Stone_Cobble"
    },
    {
      "x": -21,
      "y": 7,
      "z": 1,
      "name": "Rock_Stone_Cobble"
    },
    {
      "x": -21,
      "y": 8,
      "z": 1,
      "name": "Rock_Stone_Cobble"
    },
    {
      "x": -21,
      "y": 9,
      "z": 1,
      "name": "Rock_Stone_Cobble"
    },
    {
      "x": -21,
      "y": 0,
      "z": 2,
      "name": "Rock_Stone_Cobble"
    },
    {
      "x": -21,
      "y": 1,
      "z": 2,
      "name": "Rock_Stone_Cobble"
    },
    {
      "x": -21,
      "y": 2,
      "z": 2,
      "name": "Wood_Oak_Trunk",
      "support": 15
    },
    {
      "x": -21,
      "y": 3,
      "z": 2,
      "name": "Wood_Oak_Trunk",
      "support": 15
    },
    {
      "x": -21,
      "y": 4,
      "z": 2,
      "name": "Wood_Oak_Trunk",
      "support": 15
    },
    {
      "x": -21,
      "y": 5,
      "z": 2,
      "name": "Wood_Oak_Trunk",
      "support": 15
    },
    {
      "x": -21,
      "y": 6,
      "z": 2,
      "name": "Wood_Oak_Trunk",
      "support": 15
    },
    {
      "x": -21,
      "y": 7,
      "z": 2,
      "name": "Wood_Oak_Trunk",
      "support": 15
    },
    {
      "x": -21,
      "y": 8,
      "z": 2,
      "name": "Wood_Oak_Trunk",
      "support": 15
    },
    {
      "x": -21,
      "y": 2,
      "z": 3,
      "name": "Survival_Trap_Spike_Wood",
      "rotation": 4
    },
    {
      "x": -21,
      "y": 4,
      "z": 3,
      "name": "Survival_Trap_Spike_Wood",
      "rotation": 4
    },
    {
      "x": -21,
      "y": 6,
      "z": 3,
      "name": "Survival_Trap_Spike_Wood",
      "rotation": 4
    },
    {
      "x": -21,
      "y": 8,
      "z": 3,
      "name": "Survival_Trap_Spike_Wood",
      "rotation": 4
    },
    {
      "x": -21,
      "y": 0,
      "z": 7,
      "name": "Plant_Bush"
    },
    {
      "x": -21,
      "y": 0,
      "z": 8,
      "name": "Plant_Bush"
    },
    {
      "x": -21,
      "y": 0,
      "z": 9,
      "name": "Plant_Bush"
    },
    {
      "x": -21,
      "y": 0,
      "z": 15,
      "name": "Plant_Grass_Sharp"
    },
    {
      "x": -21,
      "y": 0,
      "z": 16,
      "name": "Plant_Grass_Sharp"
    },
    {
      "x": -21,
      "y": 0,
      "z": 17,
      "name": "Plant_Grass_Sharp"
    },
    {
      "x": -20,
      "y": 0,
      "z": -17,
      "name": "Plant_Grass_Lush_Short"
    },
    {
      "x": -20,
      "y": 0,
      "z": -16,
      "name": "Plant_Grass_Lush_Short"
    },
    {
      "x": -20,
      "y": 0,
      "z": -15,
      "name": "Plant_Grass_Lush_Short"
    },
    {
      "x": -20,
      "y": 0,
      "z": -14,
      "name": "Plant_Grass_Sharp_Short"
    },
    {
      "x": -20,
      "y": 0,
      "z": -13,
      "name": "Plant_Grass_Sharp"
    },
    {
      "x": -20,
      "y": 0,
      "z": -12,
      "name": "Plant_Grass_Lush_Short"
    },
    {
      "x": -20,
      "y": 0,
      "z": -11,
      "name": "Plant_Grass_Sharp"
    },
    {
      "x": -20,
      "y": 0,
      "z": -10,
      "name": "Plant_Grass_Sharp_Tall"
    },
    {
      "x": -20,
      "y": 0,
      "z": -9,
      "name": "Plant_Grass_Sharp"
    },
    {
      "x": -20,
      "y": 0,
      "z": -7,
      "name": "Plant_Grass_Sharp"
    },
    {
      "x": -20,
      "y": 0,
      "z": -6,
      "name": "Plant_Grass_Sharp"
    },
    {
      "x": -20,
      "y": 0,
      "z": -5,
      "name": "Plant_Grass_Sharp_Tall"
    },
    {
      "x": -20,
      "y": 0,
      "z": -4,
      "name": "Plant_Grass_Sharp"
    },
    {
      "x": -20,
      "y": 0,
      "z": -3,
      "name": "Plant_Grass_Lush_Short"
    },
    {
      "x": -20,
      "y": 3,
      "z": -3,
      "name": "Survival_Trap_Spike_Wood",
      "rotation": 7
    },
    {
      "x": -20,
      "y": 5,
      "z": -3,
      "name": "Survival_Trap_Spike_Wood",
      "rotation": 7
    },
    {
      "x": -20,
      "y": 7,
      "z": -3,
      "name": "Survival_Trap_Spike_Wood",
      "rotation": 7
    },
    {
      "x": -20,
      "y": 9,
      "z": -3,
      "name": "Deco_Bone_Full",
      "rotation": 4
    },
    {
      "x": -20,
      "y": 10,
      "z": -3,
      "name": "Deco_Bone_Full"
    },
    {
      "x": -20,
      "y": 11,
      "z": -3,
      "name": "Deco_Bone_Spike_Large"
    },
    {
      "x": -20,
      "y": 0,
      "z": -2,
      "name": "Rock_Stone_Cobble"
    },
    {
      "x": -20,
      "y": 1,
      "z": -2,
      "name": "Rock_Stone_Cobble"
    },
    {
      "x": -20,
      "y": 9,
      "z": -2,
      "name": "Deco_Bone_Full",
      "rotation": 4
    },
    {
      "x": -20,
      "y": 1,
      "z": -1,
      "name": "Rock_Stone_Cobble"
    },
    {
      "x": -20,
      "y": 2,
      "z": -1,
      "name": "Rock_Stone_Cobble"
    },
    {
      "x": -20,
      "y": 3,
      "z": -1,
      "name": "Rock_Stone_Cobble"
    },
    {
      "x": -20,
      "y": 4,
      "z": -1,
      "name": "Rock_Stone_Cobble"
    },
    {
      "x": -20,
      "y": 5,
      "z": -1,
      "name": "Rock_Stone_Cobble"
    },
    {
      "x": -20,
      "y": 6,
      "z": -1,
      "name": "Rock_Stone_Cobble"
    },
    {
      "x": -20,
      "y": 7,
      "z": -1,
      "name": "Rock_Stone_Cobble"
    },
    {
      "x": -20,
      "y": 8,
      "z": -1,
      "name": "Rock_Stone_Cobble"
    },
    {
      "x": -20,
      "y": 9,
      "z": -1,
      "name": "Deco_Bone_Full",
      "rotation": 4
    },
    {
      "x": -20,
      "y": 10,
      "z": -1,
      "name": "Deco_Bone_Spike_Large"
    },
    {
      "x": -20,
      "y": 1,
      "z": 0,
      "name": "Rock_Stone_Cobble"
    },
    {
      "x": -20,
      "y": 5,
      "z": 0,
      "name": "Wood_Softwood_Planks"
    },
    {
      "x": -20,
      "y": 6,
      "z": 0,
      "name": "Deco_Bone_Full"
    },
    {
      "x": -20,
      "y": 9,
      "z": 0,
      "name": "Deco_Bone_Full",
      "rotation": 4
    },
    {
      "x": -20,
      "y": 10,
      "z": 0,
      "name": "Deco_Bone_Full"
    },
    {
      "x": -20,
      "y": 11,
      "z": 0,
      "name": "Furniture_Village_Brazier"
    },
    {
      "x": -20,
      "y": 0,
      "z": 1,
      "name": "Plant_Grass_Sharp_Short"
    },
    {
      "x": -20,
      "y": 1,
      "z": 1,
      "name": "Rock_Stone_Cobble"
    },
    {
      "x": -20,
      "y": 5,
      "z": 1,
      "name": "Wood_Softwood_Planks"
    },
    {
      "x": -20,
      "y": 6,
      "z": 1,
      "name": "Deco_Bone_Full"
    },
    {
      "x": -20,
      "y": 9,
      "z": 1,
      "name": "Deco_Bone_Full",
      "rotation": 4
    },
    {
      "x": -20,
      "y": 10,
      "z": 1,
      "name": "Deco_Bone_Full"
    },
    {
      "x": -20,
      "y": 11,
      "z": 1,
      "name": "Furniture_Village_Brazier"
    },
    {
      "x": -20,
      "y": 1,
      "z": 2,
      "name": "Rock_Stone_Cobble"
    },
    {
      "x": -20,
      "y": 2,
      "z": 2,
      "name": "Rock_Stone_Cobble"
    },
    {
      "x": -20,
      "y": 3,
      "z": 2,
      "name": "Rock_Stone_Cobble"
    },
    {
      "x": -20,
      "y": 4,
      "z": 2,
      "name": "Rock_Stone_Cobble"
    },
    {
      "x": -20,
      "y": 5,
      "z": 2,
      "name": "Rock_Stone_Cobble"
    },
    {
      "x": -20,
      "y": 6,
      "z": 2,
      "name": "Rock_Stone_Cobble"
    },
    {
      "x": -20,
      "y": 7,
      "z": 2,
      "name": "Rock_Stone_Cobble"
    },
    {
      "x": -20,
      "y": 8,
      "z": 2,
      "name": "Rock_Stone_Cobble"
    },
    {
      "x": -20,
      "y": 9,
      "z": 2,
      "name": "Deco_Bone_Full",
      "rotation": 4
    },
    {
      "x": -20,
      "y": 10,
      "z": 2,
      "name": "Deco_Bone_Spike_Large"
    },
    {
      "x": -20,
      "y": 0,
      "z": 3,
      "name": "Rock_Stone_Cobble"
    },
    {
      "x": -20,
      "y": 1,
      "z": 3,
      "name": "Rock_Stone_Cobble"
    },
    {
      "x": -20,
      "y": 9,
      "z": 3,
      "name": "Deco_Bone_Full",
      "rotation": 4
    },
    {
      "x": -20,
      "y": 3,
      "z": 4,
      "name": "Survival_Trap_Spike_Wood",
      "rotation": 7
    },
    {
      "x": -20,
      "y": 5,
      "z": 4,
      "name": "Survival_Trap_Spike_Wood",
      "rotation": 7
    },
    {
      "x": -20,
      "y": 7,
      "z": 4,
      "name": "Survival_Trap_Spike_Wood",
      "rotation": 7
    },
    {
      "x": -20,
      "y": 9,
      "z": 4,
      "name": "Deco_Bone_Full",
      "rotation": 4
    },
    {
      "x": -20,
      "y": 10,
      "z": 4,
      "name": "Deco_Bone_Full"
    },
    {
      "x": -20,
      "y": 11,
      "z": 4,
      "name": "Deco_Bone_Spike_Large"
    },
    {
      "x": -20,
      "y": 0,
      "z": 5,
      "name": "Plant_Grass_Sharp"
    },
    {
      "x": -20,
      "y": 0,
      "z": 6,
      "name": "Plant_Grass_Sharp_Short"
    },
    {
      "x": -20,
      "y": 0,
      "z": 7,
      "name": "Plant_Bush"
    },
    {
      "x": -20,
      "y": 0,
      "z": 9,
      "name": "Plant_Bush"
    },
    {
      "x": -20,
      "y": 0,
      "z": 10,
      "name": "Plant_Grass_Lush_Short"
    },
    {
      "x": -20,
      "y": 0,
      "z": 11,
      "name": "Plant_Grass_Lush_Short"
    },
    {
      "x": -20,
      "y": 0,
      "z": 12,
      "name": "Plant_Grass_Sharp_Short"
    },
    {
      "x": -20,
      "y": 0,
      "z": 14,
      "name": "Plant_Grass_Sharp_Short"
    },
    {
      "x": -20,
      "y": 0,
      "z": 16,
      "name": "Plant_Grass_Sharp"
    },
    {
      "x": -19,
      "y": 0,
      "z": -18,
      "name": "Plant_Grass_Lush_Short"
    },
    {
      "x": -19,
      "y": 0,
      "z": -12,
      "name": "Plant_Grass_Sharp"
    },
    {
      "x": -19,
      "y": 0,
      "z": -11,
      "name": "Plant_Grass_Sharp"
    },
    {
      "x": -19,
      "y": 0,
      "z": -9,
      "name": "Plant_Grass_Sharp_Tall"
    },
    {
      "x": -19,
      "y": 0,
      "z": -8,
      "name": "Plant_Grass_Sharp"
    },
    {
      "x": -19,
      "y": 0,
      "z": -7,
      "name": "Plant_Grass_Sharp"
    },
    {
      "x": -19,
      "y": 0,
      "z": -6,
      "name": "Plant_Grass_Sharp"
    },
    {
      "x": -19,
      "y": 0,
      "z": -5,
      "name": "Plant_Grass_Lush_Short"
    },
    {
      "x": -19,
      "y": 0,
      "z": -4,
      "name": "Plant_Grass_Sharp"
    },
    {
      "x": -19,
      "y": 2,
      "z": -4,
      "name": "Survival_Trap_Spike_Wood",
      "rotation": 6
    },
    {
      "x": -19,
      "y": 4,
      "z": -4,
      "name": "Survival_Trap_Spike_Wood",
      "rotation": 6
    },
    {
      "x": -19,
      "y": 6,
      "z": -4,
      "name": "Survival_Trap_Spike_Wood",
      "rotation": 6
    },
    {
      "x": -19,
      "y": 8,
      "z": -4,
      "name": "Survival_Trap_Spike_Wood",
      "rotation": 6
    },
    {
      "x": -19,
      "y": 0,
      "z": -3,
      "name": "Rock_Stone_Cobble"
    },
    {
      "x": -19,
      "y": 1,
      "z": -3,
      "name": "Rock_Stone_Cobble"
    },
    {
      "x": -19,
      "y": 2,
      "z": -3,
      "name": "Wood_Oak_Trunk",
      "support": 15
    },
    {
      "x": -19,
      "y": 3,
      "z": -3,
      "name": "Wood_Oak_Trunk",
      "support": 15
    },
    {
      "x": -19,
      "y": 4,
      "z": -3,
      "name": "Wood_Oak_Trunk",
      "support": 15
    },
    {
      "x": -19,
      "y": 5,
      "z": -3,
      "name": "Wood_Oak_Trunk",
      "support": 15
    },
    {
      "x": -19,
      "y": 6,
      "z": -3,
      "name": "Wood_Oak_Trunk",
      "support": 15
    },
    {
      "x": -19,
      "y": 7,
      "z": -3,
      "name": "Wood_Oak_Trunk",
      "support": 15
    },
    {
      "x": -19,
      "y": 8,
      "z": -3,
      "name": "Wood_Oak_Trunk",
      "support": 15
    },
    {
      "x": -19,
      "y": 9,
      "z": -3,
      "name": "Furniture_Desert_Torch"
    },
    {
      "x": -19,
      "y": 10,
      "z": -3,
      "name": "Furniture_Desert_Torch",
      "filler": 1024
    },
    {
      "x": -19,
      "y": 0,
      "z": -2,
      "name": "Plant_Grass_Sharp"
    },
    {
      "x": -19,
      "y": 1,
      "z": -2,
      "name": "Rock_Stone_Cobble"
    },
    {
      "x": -19,
      "y": 2,
      "z": -2,
      "name": "Rock_Stone_Cobble"
    },
    {
      "x": -19,
      "y": 3,
      "z": -2,
      "name": "Rock_Stone_Cobble"
    },
    {
      "x": -19,
      "y": 4,
      "z": -2,
      "name": "Rock_Stone_Cobble"
    },
    {
      "x": -19,
      "y": 5,
      "z": -2,
      "name": "Rock_Stone_Cobble"
    },
    {
      "x": -19,
      "y": 6,
      "z": -2,
      "name": "Rock_Stone_Cobble"
    },
    {
      "x": -19,
      "y": 7,
      "z": -2,
      "name": "Rock_Stone_Cobble"
    },
    {
      "x": -19,
      "y": 8,
      "z": -2,
      "name": "Rock_Stone_Cobble"
    },
    {
      "x": -19,
      "y": 1,
      "z": -1,
      "name": "Rock_Stone_Cobble"
    },
    {
      "x": -19,
      "y": 5,
      "z": -1,
      "name": "Wood_Softwood_Planks"
    },
    {
      "x": -19,
      "y": 6,
      "z": -1,
      "name": "Deco_Bone_Full"
    },
    {
      "x": -19,
      "y": 7,
      "z": -1,
      "name": "Cloth_Block_Wool_Black"
    },
    {
      "x": -19,
      "y": 8,
      "z": -1,
      "name": "Deco_Bone_Full",
      "rotation": 4
    },
    {
      "x": -19,
      "y": 0,
      "z": 0,
      "name": "Plant_Grass_Lush_Short"
    },
    {
      "x": -19,
      "y": 1,
      "z": 0,
      "name": "Rock_Stone_Cobble"
    },
    {
      "x": -19,
      "y": 5,
      "z": 0,
      "name": "Wood_Softwood_Planks"
    },
    {
      "x": -19,
      "y": 6,
      "z": 0,
      "name": "Cloth_Block_Wool_Black"
    },
    {
      "x": -19,
      "y": 7,
      "z": 0,
      "name": "Cloth_Block_Wool_Black"
    },
    {
      "x": -19,
      "y": 8,
      "z": 0,
      "name": "Deco_Bone_Full",
      "rotation": 4
    },
    {
      "x": -19,
      "y": 9,
      "z": 0,
      "name": "Deco_Bone_Full"
    },
    {
      "x": -19,
      "y": 10,
      "z": 0,
      "name": "Rock_Lime_Cobble_Stairs",
      "rotation": 1
    },
    {
      "x": -19,
      "y": 0,
      "z": 1,
      "name": "Plant_Grass_Lush_Short"
    },
    {
      "x": -19,
      "y": 1,
      "z": 1,
      "name": "Rock_Stone_Cobble"
    },
    {
      "x": -19,
      "y": 5,
      "z": 1,
      "name": "Wood_Softwood_Planks"
    },
    {
      "x": -19,
      "y": 6,
      "z": 1,
      "name": "Cloth_Block_Wool_Black"
    },
    {
      "x": -19,
      "y": 7,
      "z": 1,
      "name": "Cloth_Block_Wool_Black"
    },
    {
      "x": -19,
      "y": 8,
      "z": 1,
      "name": "Deco_Bone_Full",
      "rotation": 4
    },
    {
      "x": -19,
      "y": 9,
      "z": 1,
      "name": "Deco_Bone_Full"
    },
    {
      "x": -19,
      "y": 10,
      "z": 1,
      "name": "Rock_Lime_Cobble_Stairs",
      "rotation": 1
    },
    {
      "x": -19,
      "y": 0,
      "z": 2,
      "name": "Plant_Grass_Sharp_Short"
    },
    {
      "x": -19,
      "y": 1,
      "z": 2,
      "name": "Rock_Stone_Cobble"
    },
    {
      "x": -19,
      "y": 5,
      "z": 2,
      "name": "Wood_Softwood_Planks"
    },
    {
      "x": -19,
      "y": 6,
      "z": 2,
      "name": "Deco_Bone_Full"
    },
    {
      "x": -19,
      "y": 7,
      "z": 2,
      "name": "Cloth_Block_Wool_Black"
    },
    {
      "x": -19,
      "y": 8,
      "z": 2,
      "name": "Deco_Bone_Full",
      "rotation": 4
    },
    {
      "x": -19,
      "y": 0,
      "z": 3,
      "name": "Plant_Grass_Lush_Short"
    },
    {
      "x": -19,
      "y": 1,
      "z": 3,
      "name": "Rock_Stone_Cobble"
    },
    {
      "x": -19,
      "y": 2,
      "z": 3,
      "name": "Rock_Stone_Cobble"
    },
    {
      "x": -19,
      "y": 3,
      "z": 3,
      "name": "Rock_Stone_Cobble"
    },
    {
      "x": -19,
      "y": 4,
      "z": 3,
      "name": "Rock_Stone_Cobble"
    },
    {
      "x": -19,
      "y": 5,
      "z": 3,
      "name": "Rock_Stone_Cobble"
    },
    {
      "x": -19,
      "y": 6,
      "z": 3,
      "name": "Rock_Stone_Cobble"
    },
    {
      "x": -19,
      "y": 7,
      "z": 3,
      "name": "Rock_Stone_Cobble"
    },
    {
      "x": -19,
      "y": 8,
      "z": 3,
      "name": "Rock_Stone_Cobble"
    },
    {
      "x": -19,
      "y": 0,
      "z": 4,
      "name": "Rock_Stone_Cobble"
    },
    {
      "x": -19,
      "y": 1,
      "z": 4,
      "name": "Rock_Stone_Cobble"
    },
    {
      "x": -19,
      "y": 2,
      "z": 4,
      "name": "Wood_Oak_Trunk",
      "support": 15
    },
    {
      "x": -19,
      "y": 3,
      "z": 4,
      "name": "Wood_Oak_Trunk",
      "support": 15
    },
    {
      "x": -19,
      "y": 4,
      "z": 4,
      "name": "Wood_Oak_Trunk",
      "support": 15
    },
    {
      "x": -19,
      "y": 5,
      "z": 4,
      "name": "Wood_Oak_Trunk",
      "support": 15
    },
    {
      "x": -19,
      "y": 6,
      "z": 4,
      "name": "Wood_Oak_Trunk",
      "support": 15
    },
    {
      "x": -19,
      "y": 7,
      "z": 4,
      "name": "Wood_Oak_Trunk",
      "support": 15
    },
    {
      "x": -19,
      "y": 8,
      "z": 4,
      "name": "Wood_Oak_Trunk",
      "support": 15
    },
    {
      "x": -19,
      "y": 9,
      "z": 4,
      "name": "Furniture_Desert_Torch"
    },
    {
      "x": -19,
      "y": 10,
      "z": 4,
      "name": "Furniture_Desert_Torch",
      "filler": 1024
    },
    {
      "x": -19,
      "y": 0,
      "z": 5,
      "name": "Plant_Grass_Sharp"
    },
    {
      "x": -19,
      "y": 2,
      "z": 5,
      "name": "Survival_Trap_Spike_Wood",
      "rotation": 4
    },
    {
      "x": -19,
      "y": 4,
      "z": 5,
      "name": "Survival_Trap_Spike_Wood",
      "rotation": 4
    },
    {
      "x": -19,
      "y": 6,
      "z": 5,
      "name": "Survival_Trap_Spike_Wood",
      "rotation": 4
    },
    {
      "x": -19,
      "y": 8,
      "z": 5,
      "name": "Survival_Trap_Spike_Wood",
      "rotation": 4
    },
    {
      "x": -19,
      "y": 0,
      "z": 7,
      "name": "Plant_Grass_Sharp"
    },
    {
      "x": -19,
      "y": 0,
      "z": 8,
      "name": "Plant_Grass_Sharp"
    },
    {
      "x": -19,
      "y": 0,
      "z": 9,
      "name": "Plant_Bush"
    },
    {
      "x": -19,
      "y": 0,
      "z": 11,
      "name": "Plant_Grass_Lush_Short"
    },
    {
      "x": -19,
      "y": 0,
      "z": 12,
      "name": "Plant_Grass_Lush_Short"
    },
    {
      "x": -19,
      "y": 0,
      "z": 13,
      "name": "Plant_Grass_Lush_Short"
    },
    {
      "x": -19,
      "y": 0,
      "z": 14,
      "name": "Plant_Grass_Sharp_Short"
    },
    {
      "x": -18,
      "y": 0,
      "z": -18,
      "name": "Plant_Grass_Sharp_Short"
    },
    {
      "x": -18,
      "y": 0,
      "z": -15,
      "name": "Plant_Grass_Sharp"
    },
    {
      "x": -18,
      "y": 0,
      "z": -12,
      "name": "Plant_Grass_Sharp"
    },
    {
      "x": -18,
      "y": 0,
      "z": -10,
      "name": "Plant_Grass_Sharp"
    },
    {
      "x": -18,
      "y": 0,
      "z": -9,
      "name": "Plant_Grass_Sharp"
    },
    {
      "x": -18,
      "y": 0,
      "z": -8,
      "name": "Plant_Grass_Sharp"
    },
    {
      "x": -18,
      "y": 0,
      "z": -7,
      "name": "Plant_Grass_Sharp"
    },
    {
      "x": -18,
      "y": 0,
      "z": -6,
      "name": "Plant_Grass_Sharp"
    },
    {
      "x": -18,
      "y": 0,
      "z": -5,
      "name": "Plant_Grass_Sharp"
    },
    {
      "x": -18,
      "y": 0,
      "z": -4,
      "name": "Rock_Stone_Cobble"
    },
    {
      "x": -18,
      "y": 1,
      "z": -4,
      "name": "Rock_Stone_Cobble"
    },
    {
      "x": -18,
      "y": 6,
      "z": -4,
      "name": "Rock_Stone_Cobble"
    },
    {
      "x": -18,
      "y": 7,
      "z": -4,
      "name": "Rock_Stone_Cobble"
    },
    {
      "x": -18,
      "y": 0,
      "z": -3,
      "name": "Plant_Grass_Sharp"
    },
    {
      "x": -18,
      "y": 1,
      "z": -3,
      "name": "Rock_Stone_Cobble"
    },
    {
      "x": -18,
      "y": 2,
      "z": -3,
      "name": "Rock_Stone_Cobble"
    },
    {
      "x": -18,
      "y": 3,
      "z": -3,
      "name": "Rock_Stone_Cobble"
    },
    {
      "x": -18,
      "y": 4,
      "z": -3,
      "name": "Rock_Stone_Cobble"
    },
    {
      "x": -18,
      "y": 5,
      "z": -3,
      "name": "Rock_Stone_Cobble"
    },
    {
      "x": -18,
      "y": 6,
      "z": -3,
      "name": "Rock_Stone_Cobble"
    },
    {
      "x": -18,
      "y": 7,
      "z": -3,
      "name": "Rock_Stone_Cobble"
    },
    {
      "x": -18,
      "y": 8,
      "z": -3,
      "name": "Rock_Stone_Cobble"
    },
    {
      "x": -18,
      "y": 0,
      "z": -2,
      "name": "Plant_Grass_Lush_Short"
    },
    {
      "x": -18,
      "y": 1,
      "z": -2,
      "name": "Rock_Stone_Cobble"
    },
    {
      "x": -18,
      "y": 5,
      "z": -2,
      "name": "Wood_Softwood_Planks"
    },
    {
      "x": -18,
      "y": 6,
      "z": -2,
      "name": "Deco_Bone_Full"
    },
    {
      "x": -18,
      "y": 7,
      "z": -2,
      "name": "Deco_Bone_Full"
    },
    {
      "x": -18,
      "y": 8,
      "z": -2,
      "name": "Rock_Lime_Cobble_Stairs",
      "rotation": 1
    },
    {
      "x": -18,
      "y": 0,
      "z": -1,
      "name": "Plant_Grass_Lush_Short"
    },
    {
      "x": -18,
      "y": 1,
      "z": -1,
      "name": "Rock_Stone_Cobble"
    },
    {
      "x": -18,
      "y": 5,
      "z": -1,
      "name": "Wood_Softwood_Planks"
    },
    {
      "x": -18,
      "y": 8,
      "z": -1,
      "name": "Deco_Bone_Full"
    },
    {
      "x": -18,
      "y": 1,
      "z": 0,
      "name": "Rock_Stone_Cobble"
    },
    {
      "x": -18,
      "y": 5,
      "z": 0,
      "name": "Wood_Softwood_Planks"
    },
    {
      "x": -18,
      "y": 8,
      "z": 0,
      "name": "Deco_Bone_Full"
    },
    {
      "x": -18,
      "y": 9,
      "z": 0,
      "name": "Deco_Bone_Full"
    },
    {
      "x": -18,
      "y": 1,
      "z": 1,
      "name": "Rock_Stone_Cobble"
    },
    {
      "x": -18,
      "y": 5,
      "z": 1,
      "name": "Wood_Softwood_Planks"
    },
    {
      "x": -18,
      "y": 8,
      "z": 1,
      "name": "Deco_Bone_Full"
    },
    {
      "x": -18,
      "y": 9,
      "z": 1,
      "name": "Deco_Bone_Full"
    },
    {
      "x": -18,
      "y": 0,
      "z": 2,
      "name": "Plant_Grass_Lush_Short"
    },
    {
      "x": -18,
      "y": 1,
      "z": 2,
      "name": "Rock_Stone_Cobble"
    },
    {
      "x": -18,
      "y": 5,
      "z": 2,
      "name": "Wood_Softwood_Planks"
    },
    {
      "x": -18,
      "y": 8,
      "z": 2,
      "name": "Deco_Bone_Full"
    },
    {
      "x": -18,
      "y": 1,
      "z": 3,
      "name": "Rock_Stone_Cobble"
    },
    {
      "x": -18,
      "y": 5,
      "z": 3,
      "name": "Wood_Softwood_Planks"
    },
    {
      "x": -18,
      "y": 6,
      "z": 3,
      "name": "Deco_Bone_Full"
    },
    {
      "x": -18,
      "y": 7,
      "z": 3,
      "name": "Deco_Bone_Full"
    },
    {
      "x": -18,
      "y": 8,
      "z": 3,
      "name": "Rock_Lime_Cobble_Stairs",
      "rotation": 1
    },
    {
      "x": -18,
      "y": 1,
      "z": 4,
      "name": "Rock_Stone_Cobble"
    },
    {
      "x": -18,
      "y": 2,
      "z": 4,
      "name": "Rock_Stone_Cobble"
    },
    {
      "x": -18,
      "y": 3,
      "z": 4,
      "name": "Rock_Stone_Cobble"
    },
    {
      "x": -18,
      "y": 4,
      "z": 4,
      "name": "Rock_Stone_Cobble"
    },
    {
      "x": -18,
      "y": 5,
      "z": 4,
      "name": "Rock_Stone_Cobble"
    },
    {
      "x": -18,
      "y": 6,
      "z": 4,
      "name": "Rock_Stone_Cobble"
    },
    {
      "x": -18,
      "y": 7,
      "z": 4,
      "name": "Rock_Stone_Cobble"
    },
    {
      "x": -18,
      "y": 8,
      "z": 4,
      "name": "Rock_Stone_Cobble"
    },
    {
      "x": -18,
      "y": 0,
      "z": 5,
      "name": "Rock_Stone_Cobble"
    },
    {
      "x": -18,
      "y": 1,
      "z": 5,
      "name": "Rock_Stone_Cobble"
    },
    {
      "x": -18,
      "y": 2,
      "z": 5,
      "name": "Rock_Stone_Cobble"
    },
    {
      "x": -18,
      "y": 3,
      "z": 5,
      "name": "Rock_Stone_Cobble"
    },
    {
      "x": -18,
      "y": 4,
      "z": 5,
      "name": "Rock_Stone_Cobble"
    },
    {
      "x": -18,
      "y": 5,
      "z": 5,
      "name": "Rock_Stone_Cobble"
    },
    {
      "x": -18,
      "y": 6,
      "z": 5,
      "name": "Rock_Stone_Cobble"
    },
    {
      "x": -18,
      "y": 7,
      "z": 5,
      "name": "Rock_Stone_Cobble"
    },
    {
      "x": -18,
      "y": 0,
      "z": 9,
      "name": "Plant_Bush"
    },
    {
      "x": -18,
      "y": 0,
      "z": 13,
      "name": "Plant_Grass_Sharp_Short"
    },
    {
      "x": -18,
      "y": 0,
      "z": 14,
      "name": "Plant_Grass_Lush_Short"
    },
    {
      "x": -17,
      "y": 0,
      "z": -15,
      "name": "Plant_Grass_Lush_Short"
    },
    {
      "x": -17,
      "y": 0,
      "z": -14,
      "name": "Plant_Grass_Lush_Short"
    },
    {
      "x": -17,
      "y": 0,
      "z": -11,
      "name": "Plant_Grass_Sharp"
    },
    {
      "x": -17,
      "y": 0,
      "z": -10,
      "name": "Plant_Grass_Sharp"
    },
    {
      "x": -17,
      "y": 0,
      "z": -9,
      "name": "Plant_Grass_Sharp"
    },
    {
      "x": -17,
      "y": 0,
      "z": -8,
      "name": "Plant_Grass_Sharp"
    },
    {
      "x": -17,
      "y": 0,
      "z": -7,
      "name": "Plant_Grass_Sharp"
    },
    {
      "x": -17,
      "y": 0,
      "z": -6,
      "name": "Plant_Grass_Sharp"
    },
    {
      "x": -17,
      "y": 0,
      "z": -5,
      "name": "Rock_Stone_Cobble"
    },
    {
      "x": -17,
      "y": 1,
      "z": -5,
      "name": "Rock_Stone_Cobble"
    },
    {
      "x": -17,
      "y": 2,
      "z": -5,
      "name": "Rock_Stone_Cobble"
    },
    {
      "x": -17,
      "y": 3,
      "z": -5,
      "name": "Rock_Stone_Cobble"
    },
    {
      "x": -17,
      "y": 4,
      "z": -5,
      "name": "Rock_Stone_Cobble"
    },
    {
      "x": -17,
      "y": 5,
      "z": -5,
      "name": "Rock_Stone_Cobble"
    },
    {
      "x": -17,
      "y": 6,
      "z": -5,
      "name": "Rock_Stone_Cobble"
    },
    {
      "x": -17,
      "y": 7,
      "z": -5,
      "name": "Rock_Stone_Cobble"
    },
    {
      "x": -17,
      "y": 0,
      "z": -4,
      "name": "Rock_Stone_Cobble"
    },
    {
      "x": -17,
      "y": 1,
      "z": -4,
      "name": "Rock_Stone_Cobble"
    },
    {
      "x": -17,
      "y": 2,
      "z": -4,
      "name": "Rock_Stone_Cobble"
    },
    {
      "x": -17,
      "y": 3,
      "z": -4,
      "name": "Rock_Stone_Cobble"
    },
    {
      "x": -17,
      "y": 4,
      "z": -4,
      "name": "Rock_Stone_Cobble"
    },
    {
      "x": -17,
      "y": 5,
      "z": -4,
      "name": "Rock_Stone_Cobble"
    },
    {
      "x": -17,
      "y": 6,
      "z": -4,
      "name": "*Furniture_Dungeon_Chest_Epic_Large_State_Definitions_CloseWindow",
      "components": {
        "Components": {
          "container": {
            "Position": {
              "X": 6,
              "Y": 128,
              "Z": 12
            },
            "Custom": false,
            "AllowViewing": true,
            "ItemContainer": {
              "Capacity": 36,
              "Items": {}
            }
          }
        }
      },
      "rotation": 1
    },
    {
      "x": -17,
      "y": 0,
      "z": -3,
      "name": "Plant_Grass_Sharp"
    },
    {
      "x": -17,
      "y": 1,
      "z": -3,
      "name": "Rock_Stone_Cobble"
    },
    {
      "x": -17,
      "y": 5,
      "z": -3,
      "name": "Wood_Softwood_Planks"
    },
    {
      "x": -17,
      "y": 6,
      "z": -3,
      "name": "*Furniture_Dungeon_Chest_Epic_Large_State_Definitions_CloseWindow",
      "filler": 32,
      "rotation": 1
    },
    {
      "x": -17,
      "y": 1,
      "z": -2,
      "name": "Rock_Stone_Cobble"
    },
    {
      "x": -17,
      "y": 5,
      "z": -2,
      "name": "Wood_Softwood_Planks"
    },
    {
      "x": -17,
      "y": 0,
      "z": -1,
      "name": "Plant_Grass_Lush_Short"
    },
    {
      "x": -17,
      "y": 1,
      "z": -1,
      "name": "Rock_Stone_Cobble"
    },
    {
      "x": -17,
      "y": 5,
      "z": -1,
      "name": "Wood_Softwood_Planks"
    },
    {
      "x": -17,
      "y": 1,
      "z": 0,
      "name": "Rock_Stone_Cobble"
    },
    {
      "x": -17,
      "y": 5,
      "z": 0,
      "name": "Wood_Softwood_Planks"
    },
    {
      "x": -17,
      "y": 0,
      "z": 1,
      "name": "Soil_Grass_Full"
    },
    {
      "x": -17,
      "y": 1,
      "z": 1,
      "name": "Rock_Stone_Cobble"
    },
    {
      "x": -17,
      "y": 5,
      "z": 1,
      "name": "Wood_Softwood_Planks"
    },
    {
      "x": -17,
      "y": 0,
      "z": 2,
      "name": "Soil_Grass_Full"
    },
    {
      "x": -17,
      "y": 1,
      "z": 2,
      "name": "Rock_Stone_Cobble"
    },
    {
      "x": -17,
      "y": 5,
      "z": 2,
      "name": "Wood_Softwood_Planks"
    },
    {
      "x": -17,
      "y": 0,
      "z": 3,
      "name": "Soil_Grass_Full"
    },
    {
      "x": -17,
      "y": 1,
      "z": 3,
      "name": "Rock_Stone_Cobble"
    },
    {
      "x": -17,
      "y": 5,
      "z": 3,
      "name": "Wood_Softwood_Planks"
    },
    {
      "x": -17,
      "y": 0,
      "z": 4,
      "name": "Soil_Grass_Full"
    },
    {
      "x": -17,
      "y": 1,
      "z": 4,
      "name": "Rock_Stone_Cobble"
    },
    {
      "x": -17,
      "y": 5,
      "z": 4,
      "name": "Wood_Softwood_Planks"
    },
    {
      "x": -17,
      "y": 6,
      "z": 4,
      "name": "Furniture_Dungeon_Chest_Epic_Large",
      "components": {
        "Components": {
          "container": {
            "Position": {
              "X": 6,
              "Y": 128,
              "Z": 20
            },
            "Custom": false,
            "AllowViewing": true,
            "ItemContainer": {
              "Capacity": 36,
              "Items": {}
            }
          }
        }
      },
      "rotation": 1
    },
    {
      "x": -17,
      "y": 0,
      "z": 5,
      "name": "Soil_Grass_Full"
    },
    {
      "x": -17,
      "y": 1,
      "z": 5,
      "name": "Rock_Stone_Cobble"
    },
    {
      "x": -17,
      "y": 2,
      "z": 5,
      "name": "Rock_Stone_Cobble"
    },
    {
      "x": -17,
      "y": 3,
      "z": 5,
      "name": "Rock_Stone_Cobble"
    },
    {
      "x": -17,
      "y": 4,
      "z": 5,
      "name": "Rock_Stone_Cobble"
    },
    {
      "x": -17,
      "y": 5,
      "z": 5,
      "name": "Rock_Stone_Cobble"
    },
    {
      "x": -17,
      "y": 6,
      "z": 5,
      "name": "Furniture_Dungeon_Chest_Epic_Large",
      "filler": 32,
      "rotation": 1
    },
    {
      "x": -17,
      "y": 0,
      "z": 6,
      "name": "Rock_Stone_Cobble"
    },
    {
      "x": -17,
      "y": 1,
      "z": 6,
      "name": "Rock_Stone_Cobble"
    },
    {
      "x": -17,
      "y": 2,
      "z": 6,
      "name": "Rock_Stone_Cobble"
    },
    {
      "x": -17,
      "y": 3,
      "z": 6,
      "name": "Rock_Stone_Cobble"
    },
    {
      "x": -17,
      "y": 4,
      "z": 6,
      "name": "Rock_Stone_Cobble"
    },
    {
      "x": -17,
      "y": 5,
      "z": 6,
      "name": "Rock_Stone_Cobble"
    },
    {
      "x": -17,
      "y": 6,
      "z": 6,
      "name": "Rock_Stone_Cobble"
    },
    {
      "x": -17,
      "y": 7,
      "z": 6,
      "name": "Rock_Stone_Cobble"
    },
    {
      "x": -17,
      "y": 0,
      "z": 11,
      "name": "Plant_Grass_Lush_Short"
    },
    {
      "x": -17,
      "y": 0,
      "z": 12,
      "name": "Plant_Grass_Lush_Short"
    },
    {
      "x": -16,
      "y": 0,
      "z": -18,
      "name": "Plant_Grass_Sharp"
    },
    {
      "x": -16,
      "y": 0,
      "z": -17,
      "name": "Plant_Grass_Sharp"
    },
    {
      "x": -16,
      "y": 0,
      "z": -16,
      "name": "Plant_Grass_Sharp"
    },
    {
      "x": -16,
      "y": 0,
      "z": -15,
      "name": "Plant_Grass_Sharp"
    },
    {
      "x": -16,
      "y": 0,
      "z": -14,
      "name": "Plant_Grass_Sharp_Short"
    },
    {
      "x": -16,
      "y": 0,
      "z": -13,
      "name": "Plant_Grass_Sharp"
    },
    {
      "x": -16,
      "y": 0,
      "z": -12,
      "name": "Plant_Grass_Sharp"
    },
    {
      "x": -16,
      "y": 0,
      "z": -11,
      "name": "Plant_Grass_Sharp"
    },
    {
      "x": -16,
      "y": 0,
      "z": -10,
      "name": "Plant_Grass_Sharp"
    },
    {
      "x": -16,
      "y": 0,
      "z": -9,
      "name": "Plant_Grass_Sharp"
    },
    {
      "x": -16,
      "y": 0,
      "z": -8,
      "name": "Plant_Grass_Sharp"
    },
    {
      "x": -16,
      "y": 0,
      "z": -7,
      "name": "Plant_Grass_Sharp"
    },
    {
      "x": -16,
      "y": 0,
      "z": -6,
      "name": "Rock_Stone_Cobble"
    },
    {
      "x": -16,
      "y": 1,
      "z": -6,
      "name": "Rock_Stone_Cobble"
    },
    {
      "x": -16,
      "y": 2,
      "z": -6,
      "name": "Rock_Stone_Cobble"
    },
    {
      "x": -16,
      "y": 3,
      "z": -6,
      "name": "Rock_Stone_Cobble"
    },
    {
      "x": -16,
      "y": 4,
      "z": -6,
      "name": "Rock_Stone_Cobble"
    },
    {
      "x": -16,
      "y": 5,
      "z": -6,
      "name": "Rock_Stone_Cobble"
    },
    {
      "x": -16,
      "y": 6,
      "z": -6,
      "name": "Rock_Stone_Cobble"
    },
    {
      "x": -16,
      "y": 7,
      "z": -6,
      "name": "Rock_Stone_Cobble"
    },
    {
      "x": -16,
      "y": 1,
      "z": -5,
      "name": "Rock_Stone_Cobble"
    },
    {
      "x": -16,
      "y": 5,
      "z": -5,
      "name": "Wood_Softwood_Planks"
    },
    {
      "x": -16,
      "y": 0,
      "z": -4,
      "name": "Plant_Grass_Sharp"
    },
    {
      "x": -16,
      "y": 1,
      "z": -4,
      "name": "Rock_Stone_Cobble"
    },
    {
      "x": -16,
      "y": 5,
      "z": -4,
      "name": "Wood_Softwood_Planks"
    },
    {
      "x": -16,
      "y": 0,
      "z": -3,
      "name": "Soil_Grass_Full"
    },
    {
      "x": -16,
      "y": 1,
      "z": -3,
      "name": "Rock_Stone_Cobble"
    },
    {
      "x": -16,
      "y": 5,
      "z": -3,
      "name": "Wood_Softwood_Planks"
    },
    {
      "x": -16,
      "y": 0,
      "z": -2,
      "name": "Soil_Grass_Full"
    },
    {
      "x": -16,
      "y": 1,
      "z": -2,
      "name": "Rock_Stone_Cobble"
    },
    {
      "x": -16,
      "y": 5,
      "z": -2,
      "name": "Wood_Softwood_Planks"
    },
    {
      "x": -16,
      "y": 0,
      "z": -1,
      "name": "Soil_Grass_Full"
    },
    {
      "x": -16,
      "y": 1,
      "z": -1,
      "name": "Rock_Stone_Cobble"
    },
    {
      "x": -16,
      "y": 5,
      "z": -1,
      "name": "Wood_Softwood_Planks"
    },
    {
      "x": -16,
      "y": 1,
      "z": 0,
      "name": "Rock_Stone_Cobble"
    },
    {
      "x": -16,
      "y": 5,
      "z": 0,
      "name": "Wood_Softwood_Planks"
    },
    {
      "x": -16,
      "y": 0,
      "z": 1,
      "name": "Soil_Grass_Full"
    },
    {
      "x": -16,
      "y": 1,
      "z": 1,
      "name": "Rock_Stone_Cobble"
    },
    {
      "x": -16,
      "y": 5,
      "z": 1,
      "name": "Wood_Softwood_Planks"
    },
    {
      "x": -16,
      "y": 0,
      "z": 2,
      "name": "Soil_Grass_Full"
    },
    {
      "x": -16,
      "y": 1,
      "z": 2,
      "name": "Rock_Stone_Cobble"
    },
    {
      "x": -16,
      "y": 5,
      "z": 2,
      "name": "Wood_Softwood_Planks"
    },
    {
      "x": -16,
      "y": 0,
      "z": 3,
      "name": "Soil_Grass_Full"
    },
    {
      "x": -16,
      "y": 1,
      "z": 3,
      "name": "Rock_Stone_Cobble"
    },
    {
      "x": -16,
      "y": 5,
      "z": 3,
      "name": "Wood_Softwood_Planks"
    },
    {
      "x": -16,
      "y": 0,
      "z": 4,
      "name": "Soil_Grass_Full"
    },
    {
      "x": -16,
      "y": 1,
      "z": 4,
      "name": "Rock_Stone_Cobble"
    },
    {
      "x": -16,
      "y": 5,
      "z": 4,
      "name": "Wood_Softwood_Planks"
    },
    {
      "x": -16,
      "y": 0,
      "z": 5,
      "name": "Soil_Grass_Full"
    },
    {
      "x": -16,
      "y": 1,
      "z": 5,
      "name": "Rock_Stone_Cobble"
    },
    {
      "x": -16,
      "y": 5,
      "z": 5,
      "name": "Wood_Softwood_Planks"
    },
    {
      "x": -16,
      "y": 0,
      "z": 6,
      "name": "Soil_Grass_Full"
    },
    {
      "x": -16,
      "y": 1,
      "z": 6,
      "name": "Rock_Stone_Cobble"
    },
    {
      "x": -16,
      "y": 5,
      "z": 6,
      "name": "Wood_Softwood_Planks"
    },
    {
      "x": -16,
      "y": 0,
      "z": 7,
      "name": "Rock_Stone_Cobble"
    },
    {
      "x": -16,
      "y": 1,
      "z": 7,
      "name": "Rock_Stone_Cobble"
    },
    {
      "x": -16,
      "y": 2,
      "z": 7,
      "name": "Rock_Stone_Cobble"
    },
    {
      "x": -16,
      "y": 3,
      "z": 7,
      "name": "Rock_Stone_Cobble"
    },
    {
      "x": -16,
      "y": 4,
      "z": 7,
      "name": "Rock_Stone_Cobble"
    },
    {
      "x": -16,
      "y": 5,
      "z": 7,
      "name": "Rock_Stone_Cobble"
    },
    {
      "x": -16,
      "y": 6,
      "z": 7,
      "name": "Rock_Stone_Cobble"
    },
    {
      "x": -16,
      "y": 7,
      "z": 7,
      "name": "Rock_Stone_Cobble"
    },
    {
      "x": -16,
      "y": 0,
      "z": 10,
      "name": "Soil_Grass_Full"
    },
    {
      "x": -16,
      "y": 0,
      "z": 11,
      "name": "Plant_Grass_Lush_Short"
    },
    {
      "x": -16,
      "y": 0,
      "z": 13,
      "name": "Plant_Flower_Common_Yellow2"
    },
    {
      "x": -15,
      "y": 0,
      "z": -18,
      "name": "Plant_Grass_Lush_Short"
    },
    {
      "x": -15,
      "y": 0,
      "z": -17,
      "name": "Plant_Grass_Sharp_Tall"
    },
    {
      "x": -15,
      "y": 0,
      "z": -16,
      "name": "Plant_Grass_Sharp"
    },
    {
      "x": -15,
      "y": 0,
      "z": -15,
      "name": "Plant_Grass_Sharp"
    },
    {
      "x": -15,
      "y": 0,
      "z": -14,
      "name": "Plant_Grass_Sharp"
    },
    {
      "x": -15,
      "y": 0,
      "z": -13,
      "name": "Plant_Grass_Sharp"
    },
    {
      "x": -15,
      "y": 0,
      "z": -12,
      "name": "Plant_Grass_Sharp"
    },
    {
      "x": -15,
      "y": 0,
      "z": -10,
      "name": "Soil_Grass_Full"
    },
    {
      "x": -15,
      "y": 1,
      "z": -10,
      "name": "Plant_Grass_Sharp"
    },
    {
      "x": -15,
      "y": 0,
      "z": -7,
      "name": "Rock_Stone_Cobble"
    },
    {
      "x": -15,
      "y": 1,
      "z": -7,
      "name": "Rock_Stone_Cobble"
    },
    {
      "x": -15,
      "y": 2,
      "z": -7,
      "name": "Rock_Stone_Cobble"
    },
    {
      "x": -15,
      "y": 3,
      "z": -7,
      "name": "Rock_Stone_Cobble"
    },
    {
      "x": -15,
      "y": 4,
      "z": -7,
      "name": "Rock_Stone_Cobble"
    },
    {
      "x": -15,
      "y": 5,
      "z": -7,
      "name": "Rock_Stone_Cobble"
    },
    {
      "x": -15,
      "y": 6,
      "z": -7,
      "name": "Rock_Stone_Cobble"
    },
    {
      "x": -15,
      "y": 7,
      "z": -7,
      "name": "Rock_Stone_Cobble"
    },
    {
      "x": -15,
      "y": 1,
      "z": -6,
      "name": "Rock_Stone_Cobble"
    },
    {
      "x": -15,
      "y": 5,
      "z": -6,
      "name": "Wood_Softwood_Planks"
    },
    {
      "x": -15,
      "y": 0,
      "z": -5,
      "name": "Soil_Grass_Full"
    },
    {
      "x": -15,
      "y": 1,
      "z": -5,
      "name": "Rock_Stone_Cobble"
    },
    {
      "x": -15,
      "y": 5,
      "z": -5,
      "name": "Wood_Softwood_Planks"
    },
    {
      "x": -15,
      "y": 0,
      "z": -4,
      "name": "Soil_Grass_Full"
    },
    {
      "x": -15,
      "y": 1,
      "z": -4,
      "name": "Rock_Stone_Cobble"
    },
    {
      "x": -15,
      "y": 5,
      "z": -4,
      "name": "Wood_Softwood_Planks"
    },
    {
      "x": -15,
      "y": 0,
      "z": -3,
      "name": "Soil_Grass_Full"
    },
    {
      "x": -15,
      "y": 1,
      "z": -3,
      "name": "Rock_Stone_Cobble"
    },
    {
      "x": -15,
      "y": 5,
      "z": -3,
      "name": "Wood_Softwood_Planks"
    },
    {
      "x": -15,
      "y": 0,
      "z": -2,
      "name": "Soil_Grass_Full"
    },
    {
      "x": -15,
      "y": 1,
      "z": -2,
      "name": "Rock_Stone_Cobble"
    },
    {
      "x": -15,
      "y": 5,
      "z": -2,
      "name": "Wood_Softwood_Planks"
    },
    {
      "x": -15,
      "y": 0,
      "z": -1,
      "name": "Soil_Grass_Full"
    },
    {
      "x": -15,
      "y": 1,
      "z": -1,
      "name": "Rock_Stone_Cobble"
    },
    {
      "x": -15,
      "y": 5,
      "z": -1,
      "name": "Wood_Softwood_Planks"
    },
    {
      "x": -15,
      "y": 6,
      "z": -1,
      "name": "Rock_Lime_Brick_Stairs",
      "rotation": 2
    },
    {
      "x": -15,
      "y": 0,
      "z": 0,
      "name": "Soil_Grass_Full"
    },
    {
      "x": -15,
      "y": 1,
      "z": 0,
      "name": "Rock_Stone_Cobble"
    },
    {
      "x": -15,
      "y": 5,
      "z": 0,
      "name": "Wood_Softwood_Planks"
    },
    {
      "x": -15,
      "y": 6,
      "z": 0,
      "name": "Rock_Lime_Brick_Smooth"
    },
    {
      "x": -15,
      "y": 7,
      "z": 0,
      "name": "Deco_Chair_Scrap",
      "filler": 1023,
      "rotation": 1
    },
    {
      "x": -15,
      "y": 8,
      "z": 0,
      "name": "Deco_Chair_Scrap",
      "filler": 2047,
      "rotation": 1
    },
    {
      "x": -15,
      "y": 9,
      "z": 0,
      "name": "Deco_Chair_Scrap",
      "filler": 3071,
      "rotation": 1
    },
    {
      "x": -15,
      "y": 10,
      "z": 0,
      "name": "Deco_Chair_Scrap",
      "filler": 4095,
      "rotation": 1
    },
    {
      "x": -15,
      "y": 0,
      "z": 1,
      "name": "Soil_Grass_Full"
    },
    {
      "x": -15,
      "y": 1,
      "z": 1,
      "name": "Rock_Stone_Cobble"
    },
    {
      "x": -15,
      "y": 5,
      "z": 1,
      "name": "Wood_Softwood_Planks"
    },
    {
      "x": -15,
      "y": 6,
      "z": 1,
      "name": "Rock_Lime_Brick_Smooth"
    },
    {
      "x": -15,
      "y": 7,
      "z": 1,
      "name": "Deco_Chair_Scrap",
      "filler": 31,
      "rotation": 1
    },
    {
      "x": -15,
      "y": 8,
      "z": 1,
      "name": "Deco_Chair_Scrap",
      "filler": 1055,
      "rotation": 1
    },
    {
      "x": -15,
      "y": 9,
      "z": 1,
      "name": "Deco_Chair_Scrap",
      "filler": 2079,
      "rotation": 1
    },
    {
      "x": -15,
      "y": 10,
      "z": 1,
      "name": "Deco_Chair_Scrap",
      "filler": 3103,
      "rotation": 1
    },
    {
      "x": -15,
      "y": 0,
      "z": 2,
      "name": "Soil_Grass_Full"
    },
    {
      "x": -15,
      "y": 1,
      "z": 2,
      "name": "Rock_Stone_Cobble"
    },
    {
      "x": -15,
      "y": 5,
      "z": 2,
      "name": "Wood_Softwood_Planks"
    },
    {
      "x": -15,
      "y": 6,
      "z": 2,
      "name": "Rock_Lime_Brick_Smooth"
    },
    {
      "x": -15,
      "y": 7,
      "z": 2,
      "name": "Deco_Chair_Scrap",
      "filler": 63,
      "rotation": 1
    },
    {
      "x": -15,
      "y": 8,
      "z": 2,
      "name": "Deco_Chair_Scrap",
      "filler": 1087,
      "rotation": 1
    },
    {
      "x": -15,
      "y": 9,
      "z": 2,
      "name": "Deco_Chair_Scrap",
      "filler": 2111,
      "rotation": 1
    },
    {
      "x": -15,
      "y": 10,
      "z": 2,
      "name": "Deco_Chair_Scrap",
      "filler": 3135,
      "rotation": 1
    },
    {
      "x": -15,
      "y": 0,
      "z": 3,
      "name": "Soil_Grass_Full"
    },
    {
      "x": -15,
      "y": 1,
      "z": 3,
      "name": "Rock_Stone_Cobble"
    },
    {
      "x": -15,
      "y": 5,
      "z": 3,
      "name": "Wood_Softwood_Planks"
    },
    {
      "x": -15,
      "y": 6,
      "z": 3,
      "name": "Rock_Lime_Brick_Stairs"
    },
    {
      "x": -15,
      "y": 0,
      "z": 4,
      "name": "Soil_Grass_Full"
    },
    {
      "x": -15,
      "y": 1,
      "z": 4,
      "name": "Rock_Stone_Cobble"
    },
    {
      "x": -15,
      "y": 5,
      "z": 4,
      "name": "Wood_Softwood_Planks"
    },
    {
      "x": -15,
      "y": 0,
      "z": 5,
      "name": "Soil_Grass_Full"
    },
    {
      "x": -15,
      "y": 1,
      "z": 5,
      "name": "Rock_Stone_Cobble"
    },
    {
      "x": -15,
      "y": 5,
      "z": 5,
      "name": "Wood_Softwood_Planks"
    },
    {
      "x": -15,
      "y": 0,
      "z": 6,
      "name": "Soil_Grass_Full"
    },
    {
      "x": -15,
      "y": 1,
      "z": 6,
      "name": "Rock_Stone_Cobble"
    },
    {
      "x": -15,
      "y": 5,
      "z": 6,
      "name": "Wood_Softwood_Planks"
    },
    {
      "x": -15,
      "y": 0,
      "z": 7,
      "name": "Soil_Grass_Full"
    },
    {
      "x": -15,
      "y": 1,
      "z": 7,
      "name": "Rock_Stone_Cobble"
    },
    {
      "x": -15,
      "y": 5,
      "z": 7,
      "name": "Wood_Softwood_Planks"
    },
    {
      "x": -15,
      "y": 0,
      "z": 8,
      "name": "Rock_Stone_Cobble"
    },
    {
      "x": -15,
      "y": 1,
      "z": 8,
      "name": "Rock_Stone_Cobble"
    },
    {
      "x": -15,
      "y": 2,
      "z": 8,
      "name": "Rock_Stone_Cobble"
    },
    {
      "x": -15,
      "y": 3,
      "z": 8,
      "name": "Rock_Stone_Cobble"
    },
    {
      "x": -15,
      "y": 4,
      "z": 8,
      "name": "Rock_Stone_Cobble"
    },
    {
      "x": -15,
      "y": 5,
      "z": 8,
      "name": "Rock_Stone_Cobble"
    },
    {
      "x": -15,
      "y": 6,
      "z": 8,
      "name": "Rock_Stone_Cobble"
    },
    {
      "x": -15,
      "y": 7,
      "z": 8,
      "name": "Rock_Stone_Cobble"
    },
    {
      "x": -15,
      "y": 0,
      "z": 9,
      "name": "Soil_Grass_Full"
    },
    {
      "x": -15,
      "y": 1,
      "z": 9,
      "name": "Plant_Grass_Sharp_Short"
    },
    {
      "x": -15,
      "y": 0,
      "z": 10,
      "name": "Soil_Grass_Full"
    },
    {
      "x": -15,
      "y": 0,
      "z": 11,
      "name": "Soil_Grass_Full"
    },
    {
      "x": -15,
      "y": 1,
      "z": 11,
      "name": "Plant_Flower_Common_Yellow2"
    },
    {
      "x": -14,
      "y": 0,
      "z": -16,
      "name": "Plant_Grass_Sharp_Tall"
    },
    {
      "x": -14,
      "y": 0,
      "z": -15,
      "name": "Plant_Grass_Sharp"
    },
    {
      "x": -14,
      "y": 0,
      "z": -11,
      "name": "Soil_Grass_Full"
    },
    {
      "x": -14,
      "y": 0,
      "z": -10,
      "name": "Soil_Grass_Full"
    },
    {
      "x": -14,
      "y": 0,
      "z": -9,
      "name": "Soil_Grass_Full"
    },
    {
      "x": -14,
      "y": 0,
      "z": -8,
      "name": "Soil_Grass_Full"
    },
    {
      "x": -14,
      "y": 1,
      "z": -8,
      "name": "Rock_Stone_Cobble"
    },
    {
      "x": -14,
      "y": 2,
      "z": -8,
      "name": "Rock_Stone_Cobble"
    },
    {
      "x": -14,
      "y": 3,
      "z": -8,
      "name": "Rock_Stone_Cobble"
    },
    {
      "x": -14,
      "y": 4,
      "z": -8,
      "name": "Rock_Stone_Cobble"
    },
    {
      "x": -14,
      "y": 5,
      "z": -8,
      "name": "Rock_Stone_Cobble"
    },
    {
      "x": -14,
      "y": 6,
      "z": -8,
      "name": "Rock_Stone_Cobble"
    },
    {
      "x": -14,
      "y": 7,
      "z": -8,
      "name": "Rock_Stone_Cobble"
    },
    {
      "x": -14,
      "y": 0,
      "z": -7,
      "name": "Soil_Grass_Full"
    },
    {
      "x": -14,
      "y": 1,
      "z": -7,
      "name": "Rock_Stone_Cobble"
    },
    {
      "x": -14,
      "y": 5,
      "z": -7,
      "name": "Wood_Softwood_Planks"
    },
    {
      "x": -14,
      "y": 0,
      "z": -6,
      "name": "Soil_Grass_Full"
    },
    {
      "x": -14,
      "y": 1,
      "z": -6,
      "name": "Rock_Stone_Cobble"
    },
    {
      "x": -14,
      "y": 5,
      "z": -6,
      "name": "Wood_Softwood_Planks"
    },
    {
      "x": -14,
      "y": 0,
      "z": -5,
      "name": "Soil_Grass_Full"
    },
    {
      "x": -14,
      "y": 1,
      "z": -5,
      "name": "Rock_Stone_Cobble"
    },
    {
      "x": -14,
      "y": 5,
      "z": -5,
      "name": "Wood_Softwood_Planks"
    },
    {
      "x": -14,
      "y": 0,
      "z": -4,
      "name": "Soil_Grass_Full"
    },
    {
      "x": -14,
      "y": 1,
      "z": -4,
      "name": "Rock_Stone_Cobble"
    },
    {
      "x": -14,
      "y": 5,
      "z": -4,
      "name": "Wood_Softwood_Planks"
    },
    {
      "x": -14,
      "y": 0,
      "z": -3,
      "name": "Soil_Grass_Full"
    },
    {
      "x": -14,
      "y": 1,
      "z": -3,
      "name": "Rock_Stone_Cobble"
    },
    {
      "x": -14,
      "y": 5,
      "z": -3,
      "name": "Wood_Softwood_Planks"
    },
    {
      "x": -14,
      "y": 0,
      "z": -2,
      "name": "Soil_Grass_Full"
    },
    {
      "x": -14,
      "y": 1,
      "z": -2,
      "name": "Rock_Stone_Cobble"
    },
    {
      "x": -14,
      "y": 5,
      "z": -2,
      "name": "Wood_Softwood_Planks"
    },
    {
      "x": -14,
      "y": 0,
      "z": -1,
      "name": "Soil_Grass_Full"
    },
    {
      "x": -14,
      "y": 1,
      "z": -1,
      "name": "Rock_Stone_Cobble"
    },
    {
      "x": -14,
      "y": 5,
      "z": -1,
      "name": "Wood_Softwood_Planks"
    },
    {
      "x": -14,
      "y": 6,
      "z": -1,
      "name": "Rock_Lime_Brick_Stairs",
      "rotation": 2
    },
    {
      "x": -14,
      "y": 0,
      "z": 0,
      "name": "Soil_Grass_Full"
    },
    {
      "x": -14,
      "y": 1,
      "z": 0,
      "name": "Rock_Stone_Cobble"
    },
    {
      "x": -14,
      "y": 5,
      "z": 0,
      "name": "Wood_Softwood_Planks"
    },
    {
      "x": -14,
      "y": 6,
      "z": 0,
      "name": "Rock_Lime_Brick_Smooth"
    },
    {
      "x": -14,
      "y": 7,
      "z": 0,
      "name": "Deco_Chair_Scrap",
      "filler": 992,
      "rotation": 1
    },
    {
      "x": -14,
      "y": 8,
      "z": 0,
      "name": "Deco_Chair_Scrap",
      "filler": 2016,
      "rotation": 1
    },
    {
      "x": -14,
      "y": 9,
      "z": 0,
      "name": "Deco_Chair_Scrap",
      "filler": 3040,
      "rotation": 1
    },
    {
      "x": -14,
      "y": 10,
      "z": 0,
      "name": "Deco_Chair_Scrap",
      "filler": 4064,
      "rotation": 1
    },
    {
      "x": -14,
      "y": 0,
      "z": 1,
      "name": "Soil_Grass_Full"
    },
    {
      "x": -14,
      "y": 1,
      "z": 1,
      "name": "Rock_Stone_Cobble"
    },
    {
      "x": -14,
      "y": 5,
      "z": 1,
      "name": "Wood_Softwood_Planks"
    },
    {
      "x": -14,
      "y": 6,
      "z": 1,
      "name": "Rock_Lime_Brick_Smooth"
    },
    {
      "x": -14,
      "y": 7,
      "z": 1,
      "name": "Deco_Chair_Scrap",
      "rotation": 1
    },
    {
      "x": -14,
      "y": 8,
      "z": 1,
      "name": "Deco_Chair_Scrap",
      "filler": 1024,
      "rotation": 1
    },
    {
      "x": -14,
      "y": 9,
      "z": 1,
      "name": "Deco_Chair_Scrap",
      "filler": 2048,
      "rotation": 1
    },
    {
      "x": -14,
      "y": 10,
      "z": 1,
      "name": "Deco_Chair_Scrap",
      "filler": 3072,
      "rotation": 1
    },
    {
      "x": -14,
      "y": 0,
      "z": 2,
      "name": "Soil_Grass_Full"
    },
    {
      "x": -14,
      "y": 1,
      "z": 2,
      "name": "Rock_Stone_Cobble"
    },
    {
      "x": -14,
      "y": 5,
      "z": 2,
      "name": "Wood_Softwood_Planks"
    },
    {
      "x": -14,
      "y": 6,
      "z": 2,
      "name": "Rock_Lime_Brick_Smooth"
    },
    {
      "x": -14,
      "y": 7,
      "z": 2,
      "name": "Deco_Chair_Scrap",
      "filler": 32,
      "rotation": 1
    },
    {
      "x": -14,
      "y": 8,
      "z": 2,
      "name": "Deco_Chair_Scrap",
      "filler": 1056,
      "rotation": 1
    },
    {
      "x": -14,
      "y": 9,
      "z": 2,
      "name": "Deco_Chair_Scrap",
      "filler": 2080,
      "rotation": 1
    },
    {
      "x": -14,
      "y": 10,
      "z": 2,
      "name": "Deco_Chair_Scrap",
      "filler": 3104,
      "rotation": 1
    },
    {
      "x": -14,
      "y": 0,
      "z": 3,
      "name": "Soil_Grass_Full"
    },
    {
      "x": -14,
      "y": 1,
      "z": 3,
      "name": "Rock_Stone_Cobble"
    },
    {
      "x": -14,
      "y": 5,
      "z": 3,
      "name": "Wood_Softwood_Planks"
    },
    {
      "x": -14,
      "y": 6,
      "z": 3,
      "name": "Rock_Lime_Brick_Stairs"
    },
    {
      "x": -14,
      "y": 0,
      "z": 4,
      "name": "Soil_Grass_Full"
    },
    {
      "x": -14,
      "y": 1,
      "z": 4,
      "name": "Rock_Stone_Cobble"
    },
    {
      "x": -14,
      "y": 5,
      "z": 4,
      "name": "Wood_Softwood_Planks"
    },
    {
      "x": -14,
      "y": 0,
      "z": 5,
      "name": "Soil_Grass_Full"
    },
    {
      "x": -14,
      "y": 1,
      "z": 5,
      "name": "Rock_Stone_Cobble"
    },
    {
      "x": -14,
      "y": 5,
      "z": 5,
      "name": "Wood_Softwood_Planks"
    },
    {
      "x": -14,
      "y": 0,
      "z": 6,
      "name": "Soil_Grass_Full"
    },
    {
      "x": -14,
      "y": 1,
      "z": 6,
      "name": "Rock_Stone_Cobble"
    },
    {
      "x": -14,
      "y": 5,
      "z": 6,
      "name": "Wood_Softwood_Planks"
    },
    {
      "x": -14,
      "y": 0,
      "z": 7,
      "name": "Soil_Grass_Full"
    },
    {
      "x": -14,
      "y": 1,
      "z": 7,
      "name": "Rock_Stone_Cobble"
    },
    {
      "x": -14,
      "y": 5,
      "z": 7,
      "name": "Wood_Softwood_Planks"
    },
    {
      "x": -14,
      "y": 0,
      "z": 8,
      "name": "Soil_Grass_Full"
    },
    {
      "x": -14,
      "y": 1,
      "z": 8,
      "name": "Rock_Stone_Cobble"
    },
    {
      "x": -14,
      "y": 5,
      "z": 8,
      "name": "Wood_Softwood_Planks"
    },
    {
      "x": -14,
      "y": 0,
      "z": 9,
      "name": "Soil_Grass_Full"
    },
    {
      "x": -14,
      "y": 1,
      "z": 9,
      "name": "Rock_Stone_Cobble"
    },
    {
      "x": -14,
      "y": 2,
      "z": 9,
      "name": "Rock_Stone_Cobble"
    },
    {
      "x": -14,
      "y": 3,
      "z": 9,
      "name": "Rock_Stone_Cobble"
    },
    {
      "x": -14,
      "y": 4,
      "z": 9,
      "name": "Rock_Stone_Cobble"
    },
    {
      "x": -14,
      "y": 5,
      "z": 9,
      "name": "Rock_Stone_Cobble"
    },
    {
      "x": -14,
      "y": 6,
      "z": 9,
      "name": "Rock_Stone_Cobble"
    },
    {
      "x": -14,
      "y": 7,
      "z": 9,
      "name": "Rock_Stone_Cobble"
    },
    {
      "x": -14,
      "y": 0,
      "z": 10,
      "name": "Soil_Grass_Full"
    },
    {
      "x": -14,
      "y": 1,
      "z": 10,
      "name": "Rock_Stone_Cobble"
    },
    {
      "x": -14,
      "y": 2,
      "z": 10,
      "name": "Rock_Stone_Cobble"
    },
    {
      "x": -14,
      "y": 3,
      "z": 10,
      "name": "Rock_Stone_Cobble"
    },
    {
      "x": -14,
      "y": 4,
      "z": 10,
      "name": "Rock_Stone_Cobble"
    },
    {
      "x": -14,
      "y": 5,
      "z": 10,
      "name": "Rock_Stone_Cobble"
    },
    {
      "x": -14,
      "y": 6,
      "z": 10,
      "name": "Rock_Stone_Cobble"
    },
    {
      "x": -14,
      "y": 7,
      "z": 10,
      "name": "Rock_Stone_Cobble"
    },
    {
      "x": -14,
      "y": 0,
      "z": 11,
      "name": "Soil_Grass_Full"
    },
    {
      "x": -14,
      "y": 0,
      "z": 12,
      "name": "Soil_Grass_Full"
    },
    {
      "x": -13,
      "y": 0,
      "z": -18,
      "name": "Plant_Grass_Sharp_Tall"
    },
    {
      "x": -13,
      "y": 0,
      "z": -17,
      "name": "Plant_Grass_Sharp_Wild"
    },
    {
      "x": -13,
      "y": 0,
      "z": -16,
      "name": "Soil_Grass_Full"
    },
    {
      "x": -13,
      "y": 1,
      "z": -16,
      "name": "Plant_Grass_Sharp"
    },
    {
      "x": -13,
      "y": 0,
      "z": -15,
      "name": "Soil_Grass_Full"
    },
    {
      "x": -13,
      "y": 1,
      "z": -15,
      "name": "Plant_Grass_Sharp_Tall"
    },
    {
      "x": -13,
      "y": 0,
      "z": -14,
      "name": "Soil_Grass_Full"
    },
    {
      "x": -13,
      "y": 0,
      "z": -13,
      "name": "Soil_Grass_Full"
    },
    {
      "x": -13,
      "y": 0,
      "z": -12,
      "name": "Soil_Grass_Full"
    },
    {
      "x": -13,
      "y": 0,
      "z": -11,
      "name": "Soil_Grass_Full"
    },
    {
      "x": -13,
      "y": 0,
      "z": -10,
      "name": "Soil_Grass_Full"
    },
    {
      "x": -13,
      "y": 0,
      "z": -9,
      "name": "Soil_Grass_Full"
    },
    {
      "x": -13,
      "y": 1,
      "z": -9,
      "name": "Rock_Stone_Cobble"
    },
    {
      "x": -13,
      "y": 2,
      "z": -9,
      "name": "Rock_Stone_Cobble"
    },
    {
      "x": -13,
      "y": 3,
      "z": -9,
      "name": "Rock_Stone_Cobble"
    },
    {
      "x": -13,
      "y": 4,
      "z": -9,
      "name": "Rock_Stone_Cobble"
    },
    {
      "x": -13,
      "y": 5,
      "z": -9,
      "name": "Rock_Stone_Cobble"
    },
    {
      "x": -13,
      "y": 6,
      "z": -9,
      "name": "Rock_Stone_Cobble"
    },
    {
      "x": -13,
      "y": 7,
      "z": -9,
      "name": "Rock_Stone_Cobble"
    },
    {
      "x": -13,
      "y": 0,
      "z": -8,
      "name": "Soil_Grass_Full"
    },
    {
      "x": -13,
      "y": 1,
      "z": -8,
      "name": "Rock_Stone_Cobble"
    },
    {
      "x": -13,
      "y": 5,
      "z": -8,
      "name": "Wood_Softwood_Planks"
    },
    {
      "x": -13,
      "y": 0,
      "z": -7,
      "name": "Soil_Grass_Full"
    },
    {
      "x": -13,
      "y": 1,
      "z": -7,
      "name": "Rock_Stone_Cobble"
    },
    {
      "x": -13,
      "y": 5,
      "z": -7,
      "name": "Wood_Softwood_Planks"
    },
    {
      "x": -13,
      "y": 0,
      "z": -6,
      "name": "Soil_Grass_Full"
    },
    {
      "x": -13,
      "y": 1,
      "z": -6,
      "name": "Rock_Stone_Cobble"
    },
    {
      "x": -13,
      "y": 5,
      "z": -6,
      "name": "Wood_Softwood_Planks"
    },
    {
      "x": -13,
      "y": 0,
      "z": -5,
      "name": "Soil_Grass_Full"
    },
    {
      "x": -13,
      "y": 1,
      "z": -5,
      "name": "Rock_Stone_Cobble"
    },
    {
      "x": -13,
      "y": 5,
      "z": -5,
      "name": "Wood_Softwood_Planks"
    },
    {
      "x": -13,
      "y": 0,
      "z": -4,
      "name": "Soil_Grass_Full"
    },
    {
      "x": -13,
      "y": 1,
      "z": -4,
      "name": "Rock_Stone_Cobble"
    },
    {
      "x": -13,
      "y": 5,
      "z": -4,
      "name": "Wood_Softwood_Planks"
    },
    {
      "x": -13,
      "y": 0,
      "z": -3,
      "name": "Soil_Grass_Full"
    },
    {
      "x": -13,
      "y": 1,
      "z": -3,
      "name": "Rock_Stone_Cobble"
    },
    {
      "x": -13,
      "y": 5,
      "z": -3,
      "name": "Wood_Softwood_Planks"
    },
    {
      "x": -13,
      "y": 0,
      "z": -2,
      "name": "Soil_Grass_Full"
    },
    {
      "x": -13,
      "y": 1,
      "z": -2,
      "name": "Rock_Stone_Cobble"
    },
    {
      "x": -13,
      "y": 5,
      "z": -2,
      "name": "Wood_Softwood_Planks"
    },
    {
      "x": -13,
      "y": 0,
      "z": -1,
      "name": "Soil_Grass_Full"
    },
    {
      "x": -13,
      "y": 1,
      "z": -1,
      "name": "Rock_Stone_Cobble"
    },
    {
      "x": -13,
      "y": 5,
      "z": -1,
      "name": "Wood_Softwood_Planks"
    },
    {
      "x": -13,
      "y": 6,
      "z": -1,
      "name": "Rock_Lime_Brick_Stairs",
      "rotation": 2
    },
    {
      "x": -13,
      "y": 0,
      "z": 0,
      "name": "Soil_Grass_Full"
    },
    {
      "x": -13,
      "y": 1,
      "z": 0,
      "name": "Rock_Stone_Cobble"
    },
    {
      "x": -13,
      "y": 5,
      "z": 0,
      "name": "Wood_Softwood_Planks"
    },
    {
      "x": -13,
      "y": 6,
      "z": 0,
      "name": "Rock_Lime_Brick_Smooth"
    },
    {
      "x": -13,
      "y": 7,
      "z": 0,
      "name": "Furniture_Feran_Candle"
    },
    {
      "x": -13,
      "y": 0,
      "z": 1,
      "name": "Soil_Grass_Full"
    },
    {
      "x": -13,
      "y": 1,
      "z": 1,
      "name": "Rock_Stone_Cobble"
    },
    {
      "x": -13,
      "y": 5,
      "z": 1,
      "name": "Wood_Softwood_Planks"
    },
    {
      "x": -13,
      "y": 6,
      "z": 1,
      "name": "Rock_Lime_Brick_Smooth"
    },
    {
      "x": -13,
      "y": 0,
      "z": 2,
      "name": "Soil_Grass_Full"
    },
    {
      "x": -13,
      "y": 1,
      "z": 2,
      "name": "Rock_Stone_Cobble"
    },
    {
      "x": -13,
      "y": 5,
      "z": 2,
      "name": "Wood_Softwood_Planks"
    },
    {
      "x": -13,
      "y": 6,
      "z": 2,
      "name": "Rock_Lime_Brick_Smooth"
    },
    {
      "x": -13,
      "y": 0,
      "z": 3,
      "name": "Soil_Grass_Full"
    },
    {
      "x": -13,
      "y": 1,
      "z": 3,
      "name": "Rock_Stone_Cobble"
    },
    {
      "x": -13,
      "y": 5,
      "z": 3,
      "name": "Wood_Softwood_Planks"
    },
    {
      "x": -13,
      "y": 6,
      "z": 3,
      "name": "Rock_Lime_Brick_Stairs"
    },
    {
      "x": -13,
      "y": 0,
      "z": 4,
      "name": "Soil_Grass_Full"
    },
    {
      "x": -13,
      "y": 1,
      "z": 4,
      "name": "Rock_Stone_Cobble"
    },
    {
      "x": -13,
      "y": 5,
      "z": 4,
      "name": "Wood_Softwood_Planks"
    },
    {
      "x": -13,
      "y": 0,
      "z": 5,
      "name": "Soil_Grass_Full"
    },
    {
      "x": -13,
      "y": 1,
      "z": 5,
      "name": "Rock_Stone_Cobble"
    },
    {
      "x": -13,
      "y": 5,
      "z": 5,
      "name": "Wood_Softwood_Planks"
    },
    {
      "x": -13,
      "y": 0,
      "z": 6,
      "name": "Soil_Grass_Full"
    },
    {
      "x": -13,
      "y": 1,
      "z": 6,
      "name": "Rock_Stone_Cobble"
    },
    {
      "x": -13,
      "y": 5,
      "z": 6,
      "name": "Wood_Softwood_Planks"
    },
    {
      "x": -13,
      "y": 0,
      "z": 7,
      "name": "Soil_Grass_Full"
    },
    {
      "x": -13,
      "y": 1,
      "z": 7,
      "name": "Rock_Stone_Cobble"
    },
    {
      "x": -13,
      "y": 5,
      "z": 7,
      "name": "Wood_Softwood_Planks"
    },
    {
      "x": -13,
      "y": 0,
      "z": 8,
      "name": "Soil_Grass_Full"
    },
    {
      "x": -13,
      "y": 1,
      "z": 8,
      "name": "Rock_Stone_Cobble"
    },
    {
      "x": -13,
      "y": 5,
      "z": 8,
      "name": "Wood_Softwood_Planks"
    },
    {
      "x": -13,
      "y": 0,
      "z": 9,
      "name": "Soil_Grass_Full"
    },
    {
      "x": -13,
      "y": 1,
      "z": 9,
      "name": "Rock_Stone_Cobble"
    },
    {
      "x": -13,
      "y": 5,
      "z": 9,
      "name": "Wood_Softwood_Planks"
    },
    {
      "x": -13,
      "y": 0,
      "z": 10,
      "name": "Soil_Grass_Full"
    },
    {
      "x": -13,
      "y": 1,
      "z": 10,
      "name": "Rock_Stone_Cobble"
    },
    {
      "x": -13,
      "y": 5,
      "z": 10,
      "name": "Wood_Softwood_Planks"
    },
    {
      "x": -13,
      "y": 0,
      "z": 11,
      "name": "Soil_Grass_Full"
    },
    {
      "x": -13,
      "y": 1,
      "z": 11,
      "name": "Rock_Stone_Cobble"
    },
    {
      "x": -13,
      "y": 2,
      "z": 11,
      "name": "Rock_Stone_Cobble"
    },
    {
      "x": -13,
      "y": 3,
      "z": 11,
      "name": "Rock_Stone_Cobble"
    },
    {
      "x": -13,
      "y": 4,
      "z": 11,
      "name": "Rock_Stone_Cobble"
    },
    {
      "x": -13,
      "y": 5,
      "z": 11,
      "name": "Rock_Stone_Cobble"
    },
    {
      "x": -13,
      "y": 6,
      "z": 11,
      "name": "Rock_Stone_Cobble"
    },
    {
      "x": -13,
      "y": 7,
      "z": 11,
      "name": "Rock_Stone_Cobble"
    },
    {
      "x": -13,
      "y": 0,
      "z": 12,
      "name": "Soil_Grass_Full"
    },
    {
      "x": -13,
      "y": 0,
      "z": 13,
      "name": "Soil_Grass_Full"
    },
    {
      "x": -13,
      "y": 0,
      "z": 14,
      "name": "Soil_Grass_Full"
    },
    {
      "x": -12,
      "y": 0,
      "z": -18,
      "name": "Soil_Grass_Full"
    },
    {
      "x": -12,
      "y": 1,
      "z": -18,
      "name": "Plant_Grass_Sharp"
    },
    {
      "x": -12,
      "y": 0,
      "z": -17,
      "name": "Soil_Grass_Full"
    },
    {
      "x": -12,
      "y": 1,
      "z": -17,
      "name": "Plant_Grass_Sharp_Wild"
    },
    {
      "x": -12,
      "y": 0,
      "z": -16,
      "name": "Soil_Grass_Full"
    },
    {
      "x": -12,
      "y": 1,
      "z": -16,
      "name": "Plant_Grass_Sharp"
    },
    {
      "x": -12,
      "y": 0,
      "z": -15,
      "name": "Soil_Grass_Full"
    },
    {
      "x": -12,
      "y": 0,
      "z": -14,
      "name": "Soil_Grass_Full"
    },
    {
      "x": -12,
      "y": 0,
      "z": -13,
      "name": "Soil_Grass_Full"
    },
    {
      "x": -12,
      "y": 0,
      "z": -12,
      "name": "Soil_Grass_Full"
    },
    {
      "x": -12,
      "y": 0,
      "z": -11,
      "name": "Soil_Grass_Full"
    },
    {
      "x": -12,
      "y": 0,
      "z": -10,
      "name": "Soil_Grass_Full"
    },
    {
      "x": -12,
      "y": 1,
      "z": -10,
      "name": "Rock_Stone_Cobble"
    },
    {
      "x": -12,
      "y": 2,
      "z": -10,
      "name": "Rock_Stone_Cobble"
    },
    {
      "x": -12,
      "y": 3,
      "z": -10,
      "name": "Rock_Stone_Cobble"
    },
    {
      "x": -12,
      "y": 4,
      "z": -10,
      "name": "Rock_Stone_Cobble"
    },
    {
      "x": -12,
      "y": 5,
      "z": -10,
      "name": "Rock_Stone_Cobble"
    },
    {
      "x": -12,
      "y": 6,
      "z": -10,
      "name": "Rock_Stone_Cobble"
    },
    {
      "x": -12,
      "y": 7,
      "z": -10,
      "name": "Rock_Stone_Cobble"
    },
    {
      "x": -12,
      "y": 0,
      "z": -9,
      "name": "Soil_Grass_Full"
    },
    {
      "x": -12,
      "y": 1,
      "z": -9,
      "name": "Rock_Stone_Cobble"
    },
    {
      "x": -12,
      "y": 5,
      "z": -9,
      "name": "Wood_Softwood_Planks"
    },
    {
      "x": -12,
      "y": 0,
      "z": -8,
      "name": "Soil_Grass_Full"
    },
    {
      "x": -12,
      "y": 1,
      "z": -8,
      "name": "Rock_Stone_Cobble"
    },
    {
      "x": -12,
      "y": 5,
      "z": -8,
      "name": "Wood_Softwood_Planks"
    },
    {
      "x": -12,
      "y": 0,
      "z": -7,
      "name": "Soil_Grass_Full"
    },
    {
      "x": -12,
      "y": 1,
      "z": -7,
      "name": "Rock_Stone_Cobble"
    },
    {
      "x": -12,
      "y": 5,
      "z": -7,
      "name": "Wood_Softwood_Planks"
    },
    {
      "x": -12,
      "y": 0,
      "z": -6,
      "name": "Soil_Grass_Full"
    },
    {
      "x": -12,
      "y": 1,
      "z": -6,
      "name": "Rock_Stone_Cobble"
    },
    {
      "x": -12,
      "y": 5,
      "z": -6,
      "name": "Wood_Softwood_Planks"
    },
    {
      "x": -12,
      "y": 0,
      "z": -5,
      "name": "Soil_Grass_Full"
    },
    {
      "x": -12,
      "y": 1,
      "z": -5,
      "name": "Rock_Stone_Cobble"
    },
    {
      "x": -12,
      "y": 5,
      "z": -5,
      "name": "Wood_Softwood_Planks"
    },
    {
      "x": -12,
      "y": 6,
      "z": -5,
      "name": "Furniture_Desert_Torch"
    },
    {
      "x": -12,
      "y": 7,
      "z": -5,
      "name": "Furniture_Desert_Torch",
      "filler": 1024
    },
    {
      "x": -12,
      "y": 0,
      "z": -4,
      "name": "Soil_Grass_Full"
    },
    {
      "x": -12,
      "y": 1,
      "z": -4,
      "name": "Rock_Stone_Cobble"
    },
    {
      "x": -12,
      "y": 4,
      "z": -4,
      "name": "Rock_Stone_Cobble"
    },
    {
      "x": -12,
      "y": 5,
      "z": -4,
      "name": "Rock_Stone_Cobble"
    },
    {
      "x": -12,
      "y": 6,
      "z": -4,
      "name": "*Rock_Stone_Brick_Wall_State_Definitions_Corner",
      "rotation": 1
    },
    {
      "x": -12,
      "y": 0,
      "z": -3,
      "name": "Soil_Grass_Full"
    },
    {
      "x": -12,
      "y": 1,
      "z": -3,
      "name": "Soil_Dirt_Dry"
    },
    {
      "x": -12,
      "y": 2,
      "z": -3,
      "name": "Rock_Stone_Cobble"
    },
    {
      "x": -12,
      "y": 3,
      "z": -3,
      "name": "Rock_Stone_Cobble"
    },
    {
      "x": -12,
      "y": 4,
      "z": -3,
      "name": "Rock_Stone_Cobble"
    },
    {
      "x": -12,
      "y": 5,
      "z": -3,
      "name": "Rock_Stone_Cobble"
    },
    {
      "x": -12,
      "y": 6,
      "z": -3,
      "name": "Rock_Stone_Brick_Wall",
      "rotation": 1
    },
    {
      "x": -12,
      "y": 0,
      "z": -2,
      "name": "Soil_Grass_Full"
    },
    {
      "x": -12,
      "y": 1,
      "z": -2,
      "name": "Soil_Dirt_Dry"
    },
    {
      "x": -12,
      "y": 2,
      "z": -2,
      "name": "Wood_Oak_Trunk",
      "support": 15
    },
    {
      "x": -12,
      "y": 3,
      "z": -2,
      "name": "Wood_Oak_Trunk",
      "support": 15
    },
    {
      "x": -12,
      "y": 4,
      "z": -2,
      "name": "Wood_Oak_Trunk",
      "support": 15
    },
    {
      "x": -12,
      "y": 5,
      "z": -2,
      "name": "Wood_Oak_Trunk",
      "support": 15
    },
    {
      "x": -12,
      "y": 6,
      "z": -2,
      "name": "Rock_Stone_Brick_Wall",
      "rotation": 1
    },
    {
      "x": -12,
      "y": 0,
      "z": -1,
      "name": "Soil_Grass_Full"
    },
    {
      "x": -12,
      "y": 1,
      "z": -1,
      "name": "Soil_Dirt_Dry"
    },
    {
      "x": -12,
      "y": 2,
      "z": -1,
      "name": "Rock_Stone_Cobble"
    },
    {
      "x": -12,
      "y": 3,
      "z": -1,
      "name": "Rock_Stone_Cobble"
    },
    {
      "x": -12,
      "y": 4,
      "z": -1,
      "name": "Rock_Stone_Cobble"
    },
    {
      "x": -12,
      "y": 5,
      "z": -1,
      "name": "Rock_Stone_Cobble"
    },
    {
      "x": -12,
      "y": 6,
      "z": -1,
      "name": "Rock_Stone_Brick_Wall",
      "rotation": 1
    },
    {
      "x": -12,
      "y": 0,
      "z": 0,
      "name": "Soil_Grass_Full"
    },
    {
      "x": -12,
      "y": 1,
      "z": 0,
      "name": "Soil_Dirt_Dry"
    },
    {
      "x": -12,
      "y": 2,
      "z": 0,
      "name": "Wood_Oak_Trunk",
      "support": 15
    },
    {
      "x": -12,
      "y": 3,
      "z": 0,
      "name": "Wood_Oak_Trunk",
      "support": 15
    },
    {
      "x": -12,
      "y": 4,
      "z": 0,
      "name": "Wood_Oak_Trunk",
      "support": 15
    },
    {
      "x": -12,
      "y": 5,
      "z": 0,
      "name": "Wood_Oak_Trunk",
      "support": 15
    },
    {
      "x": -12,
      "y": 6,
      "z": 0,
      "name": "Rock_Stone_Brick_Wall",
      "rotation": 1
    },
    {
      "x": -12,
      "y": 0,
      "z": 1,
      "name": "Soil_Grass_Full"
    },
    {
      "x": -12,
      "y": 1,
      "z": 1,
      "name": "Soil_Dirt_Dry"
    },
    {
      "x": -12,
      "y": 2,
      "z": 1,
      "name": "Rock_Stone_Cobble"
    },
    {
      "x": -12,
      "y": 3,
      "z": 1,
      "name": "Rock_Stone_Cobble"
    },
    {
      "x": -12,
      "y": 4,
      "z": 1,
      "name": "Rock_Stone_Cobble"
    },
    {
      "x": -12,
      "y": 5,
      "z": 1,
      "name": "Rock_Stone_Cobble"
    },
    {
      "x": -12,
      "y": 6,
      "z": 1,
      "name": "Rock_Stone_Brick_Wall",
      "rotation": 1
    },
    {
      "x": -12,
      "y": 0,
      "z": 2,
      "name": "Soil_Grass_Full"
    },
    {
      "x": -12,
      "y": 1,
      "z": 2,
      "name": "Soil_Dirt_Dry"
    },
    {
      "x": -12,
      "y": 2,
      "z": 2,
      "name": "Wood_Oak_Trunk",
      "support": 15
    },
    {
      "x": -12,
      "y": 3,
      "z": 2,
      "name": "Wood_Oak_Trunk",
      "support": 15
    },
    {
      "x": -12,
      "y": 4,
      "z": 2,
      "name": "Wood_Oak_Trunk",
      "support": 15
    },
    {
      "x": -12,
      "y": 5,
      "z": 2,
      "name": "Wood_Oak_Trunk",
      "support": 15
    },
    {
      "x": -12,
      "y": 6,
      "z": 2,
      "name": "Rock_Stone_Brick_Wall",
      "rotation": 1
    },
    {
      "x": -12,
      "y": 0,
      "z": 3,
      "name": "Soil_Grass_Full"
    },
    {
      "x": -12,
      "y": 1,
      "z": 3,
      "name": "Rock_Stone_Cobble"
    },
    {
      "x": -12,
      "y": 2,
      "z": 3,
      "name": "Rock_Stone_Cobble"
    },
    {
      "x": -12,
      "y": 3,
      "z": 3,
      "name": "Rock_Stone_Cobble"
    },
    {
      "x": -12,
      "y": 4,
      "z": 3,
      "name": "Rock_Stone_Cobble"
    },
    {
      "x": -12,
      "y": 5,
      "z": 3,
      "name": "Rock_Stone_Cobble"
    },
    {
      "x": -12,
      "y": 6,
      "z": 3,
      "name": "Rock_Stone_Brick_Wall",
      "rotation": 1
    },
    {
      "x": -12,
      "y": 0,
      "z": 4,
      "name": "Soil_Grass_Full"
    },
    {
      "x": -12,
      "y": 1,
      "z": 4,
      "name": "Soil_Dirt_Dry"
    },
    {
      "x": -12,
      "y": 2,
      "z": 4,
      "name": "Wood_Oak_Trunk",
      "support": 15
    },
    {
      "x": -12,
      "y": 3,
      "z": 4,
      "name": "Wood_Oak_Trunk",
      "support": 15
    },
    {
      "x": -12,
      "y": 4,
      "z": 4,
      "name": "Wood_Oak_Trunk",
      "support": 15
    },
    {
      "x": -12,
      "y": 5,
      "z": 4,
      "name": "Wood_Oak_Trunk",
      "support": 15
    },
    {
      "x": -12,
      "y": 6,
      "z": 4,
      "name": "Rock_Stone_Brick_Wall",
      "rotation": 1
    },
    {
      "x": -12,
      "y": 0,
      "z": 5,
      "name": "Soil_Grass_Full"
    },
    {
      "x": -12,
      "y": 1,
      "z": 5,
      "name": "Soil_Dirt_Dry"
    },
    {
      "x": -12,
      "y": 2,
      "z": 5,
      "name": "Rock_Stone_Cobble"
    },
    {
      "x": -12,
      "y": 3,
      "z": 5,
      "name": "Rock_Stone_Cobble"
    },
    {
      "x": -12,
      "y": 4,
      "z": 5,
      "name": "Rock_Stone_Cobble"
    },
    {
      "x": -12,
      "y": 5,
      "z": 5,
      "name": "Rock_Stone_Cobble"
    },
    {
      "x": -12,
      "y": 6,
      "z": 5,
      "name": "Rock_Stone_Brick_Wall",
      "rotation": 1
    },
    {
      "x": -12,
      "y": 0,
      "z": 6,
      "name": "Soil_Grass_Full"
    },
    {
      "x": -12,
      "y": 1,
      "z": 6,
      "name": "Rock_Stone_Cobble"
    },
    {
      "x": -12,
      "y": 4,
      "z": 6,
      "name": "Rock_Stone_Cobble"
    },
    {
      "x": -12,
      "y": 5,
      "z": 6,
      "name": "Rock_Stone_Cobble"
    },
    {
      "x": -12,
      "y": 6,
      "z": 6,
      "name": "*Rock_Stone_Brick_Wall_State_Definitions_Corner",
      "rotation": 2
    },
    {
      "x": -12,
      "y": 0,
      "z": 7,
      "name": "Soil_Grass_Full"
    },
    {
      "x": -12,
      "y": 1,
      "z": 7,
      "name": "Rock_Stone_Cobble"
    },
    {
      "x": -12,
      "y": 5,
      "z": 7,
      "name": "Wood_Softwood_Planks"
    },
    {
      "x": -12,
      "y": 6,
      "z": 7,
      "name": "Furniture_Desert_Torch"
    },
    {
      "x": -12,
      "y": 7,
      "z": 7,
      "name": "Furniture_Desert_Torch",
      "filler": 1024
    },
    {
      "x": -12,
      "y": 0,
      "z": 8,
      "name": "Soil_Grass_Full"
    },
    {
      "x": -12,
      "y": 1,
      "z": 8,
      "name": "Rock_Stone_Cobble"
    },
    {
      "x": -12,
      "y": 5,
      "z": 8,
      "name": "Wood_Softwood_Planks"
    },
    {
      "x": -12,
      "y": 0,
      "z": 9,
      "name": "Soil_Grass_Full"
    },
    {
      "x": -12,
      "y": 1,
      "z": 9,
      "name": "Rock_Stone_Cobble"
    },
    {
      "x": -12,
      "y": 5,
      "z": 9,
      "name": "Wood_Softwood_Planks"
    },
    {
      "x": -12,
      "y": 0,
      "z": 10,
      "name": "Soil_Grass_Full"
    },
    {
      "x": -12,
      "y": 1,
      "z": 10,
      "name": "Rock_Stone_Cobble"
    },
    {
      "x": -12,
      "y": 5,
      "z": 10,
      "name": "Wood_Softwood_Planks"
    },
    {
      "x": -12,
      "y": 0,
      "z": 11,
      "name": "Soil_Grass_Full"
    },
    {
      "x": -12,
      "y": 1,
      "z": 11,
      "name": "Rock_Stone_Cobble"
    },
    {
      "x": -12,
      "y": 5,
      "z": 11,
      "name": "Wood_Softwood_Planks"
    },
    {
      "x": -12,
      "y": 0,
      "z": 12,
      "name": "Soil_Grass_Full"
    },
    {
      "x": -12,
      "y": 1,
      "z": 12,
      "name": "Rock_Stone_Cobble"
    },
    {
      "x": -12,
      "y": 2,
      "z": 12,
      "name": "Rock_Stone_Cobble"
    },
    {
      "x": -12,
      "y": 3,
      "z": 12,
      "name": "Rock_Stone_Cobble"
    },
    {
      "x": -12,
      "y": 4,
      "z": 12,
      "name": "Rock_Stone_Cobble"
    },
    {
      "x": -12,
      "y": 5,
      "z": 12,
      "name": "Rock_Stone_Cobble"
    },
    {
      "x": -12,
      "y": 6,
      "z": 12,
      "name": "Rock_Stone_Cobble"
    },
    {
      "x": -12,
      "y": 7,
      "z": 12,
      "name": "Rock_Stone_Cobble"
    },
    {
      "x": -12,
      "y": 0,
      "z": 13,
      "name": "Soil_Grass_Full"
    },
    {
      "x": -12,
      "y": 0,
      "z": 14,
      "name": "Soil_Grass_Full"
    },
    {
      "x": -12,
      "y": 0,
      "z": 15,
      "name": "Soil_Grass_Full"
    },
    {
      "x": -12,
      "y": 0,
      "z": 16,
      "name": "Soil_Dirt_Dry"
    },
    {
      "x": -12,
      "y": 0,
      "z": 17,
      "name": "Soil_Dirt_Dry"
    },
    {
      "x": -11,
      "y": 0,
      "z": -18,
      "name": "Soil_Grass_Full"
    },
    {
      "x": -11,
      "y": 1,
      "z": -18,
      "name": "Plant_Grass_Lush_Short"
    },
    {
      "x": -11,
      "y": 0,
      "z": -17,
      "name": "Soil_Grass_Full"
    },
    {
      "x": -11,
      "y": 1,
      "z": -17,
      "name": "Plant_Grass_Sharp"
    },
    {
      "x": -11,
      "y": 0,
      "z": -16,
      "name": "Soil_Grass_Full"
    },
    {
      "x": -11,
      "y": 1,
      "z": -16,
      "name": "Plant_Grass_Sharp"
    },
    {
      "x": -11,
      "y": 0,
      "z": -15,
      "name": "Soil_Grass_Full"
    },
    {
      "x": -11,
      "y": 1,
      "z": -15,
      "name": "Plant_Grass_Lush_Short"
    },
    {
      "x": -11,
      "y": 0,
      "z": -14,
      "name": "Soil_Grass_Full"
    },
    {
      "x": -11,
      "y": 0,
      "z": -13,
      "name": "Soil_Grass_Full"
    },
    {
      "x": -11,
      "y": 1,
      "z": -13,
      "name": "Rock_Stone_Cobble"
    },
    {
      "x": -11,
      "y": 2,
      "z": -13,
      "name": "Rock_Stone_Cobble"
    },
    {
      "x": -11,
      "y": 3,
      "z": -13,
      "name": "Rock_Stone_Cobble"
    },
    {
      "x": -11,
      "y": 4,
      "z": -13,
      "name": "Rock_Stone_Cobble"
    },
    {
      "x": -11,
      "y": 5,
      "z": -13,
      "name": "Rock_Stone_Cobble"
    },
    {
      "x": -11,
      "y": 6,
      "z": -13,
      "name": "Rock_Stone_Cobble"
    },
    {
      "x": -11,
      "y": 7,
      "z": -13,
      "name": "Rock_Stone_Cobble"
    },
    {
      "x": -11,
      "y": 0,
      "z": -12,
      "name": "Soil_Grass_Full"
    },
    {
      "x": -11,
      "y": 1,
      "z": -12,
      "name": "Rock_Stone_Cobble"
    },
    {
      "x": -11,
      "y": 2,
      "z": -12,
      "name": "Rock_Stone_Cobble"
    },
    {
      "x": -11,
      "y": 3,
      "z": -12,
      "name": "Rock_Stone_Cobble"
    },
    {
      "x": -11,
      "y": 4,
      "z": -12,
      "name": "Rock_Stone_Cobble"
    },
    {
      "x": -11,
      "y": 5,
      "z": -12,
      "name": "Rock_Stone_Cobble"
    },
    {
      "x": -11,
      "y": 6,
      "z": -12,
      "name": "Rock_Stone_Cobble"
    },
    {
      "x": -11,
      "y": 7,
      "z": -12,
      "name": "Rock_Stone_Cobble"
    },
    {
      "x": -11,
      "y": 0,
      "z": -11,
      "name": "Soil_Grass_Full"
    },
    {
      "x": -11,
      "y": 1,
      "z": -11,
      "name": "Rock_Stone_Cobble"
    },
    {
      "x": -11,
      "y": 2,
      "z": -11,
      "name": "Rock_Stone_Cobble"
    },
    {
      "x": -11,
      "y": 3,
      "z": -11,
      "name": "Rock_Stone_Cobble"
    },
    {
      "x": -11,
      "y": 4,
      "z": -11,
      "name": "Rock_Stone_Cobble"
    },
    {
      "x": -11,
      "y": 5,
      "z": -11,
      "name": "Rock_Stone_Cobble"
    },
    {
      "x": -11,
      "y": 6,
      "z": -11,
      "name": "Rock_Stone_Cobble"
    },
    {
      "x": -11,
      "y": 7,
      "z": -11,
      "name": "Rock_Stone_Cobble"
    },
    {
      "x": -11,
      "y": 0,
      "z": -10,
      "name": "Soil_Grass_Full"
    },
    {
      "x": -11,
      "y": 1,
      "z": -10,
      "name": "Rock_Stone_Cobble"
    },
    {
      "x": -11,
      "y": 5,
      "z": -10,
      "name": "Wood_Softwood_Planks"
    },
    {
      "x": -11,
      "y": 0,
      "z": -9,
      "name": "Soil_Grass_Full"
    },
    {
      "x": -11,
      "y": 1,
      "z": -9,
      "name": "Rock_Stone_Cobble"
    },
    {
      "x": -11,
      "y": 5,
      "z": -9,
      "name": "Wood_Softwood_Planks"
    },
    {
      "x": -11,
      "y": 0,
      "z": -8,
      "name": "Soil_Grass_Full"
    },
    {
      "x": -11,
      "y": 1,
      "z": -8,
      "name": "Rock_Stone_Cobble"
    },
    {
      "x": -11,
      "y": 5,
      "z": -8,
      "name": "Wood_Softwood_Planks"
    },
    {
      "x": -11,
      "y": 0,
      "z": -7,
      "name": "Soil_Grass_Full"
    },
    {
      "x": -11,
      "y": 1,
      "z": -7,
      "name": "Rock_Stone_Cobble"
    },
    {
      "x": -11,
      "y": 5,
      "z": -7,
      "name": "Wood_Softwood_Planks"
    },
    {
      "x": -11,
      "y": 0,
      "z": -6,
      "name": "Soil_Grass_Full"
    },
    {
      "x": -11,
      "y": 1,
      "z": -6,
      "name": "Rock_Stone_Cobble"
    },
    {
      "x": -11,
      "y": 4,
      "z": -6,
      "name": "Rock_Stone_Cobble"
    },
    {
      "x": -11,
      "y": 5,
      "z": -6,
      "name": "Rock_Stone_Cobble"
    },
    {
      "x": -11,
      "y": 6,
      "z": -6,
      "name": "*Rock_Stone_Brick_Wall_State_Definitions_Corner",
      "rotation": 1
    },
    {
      "x": -11,
      "y": 0,
      "z": -5,
      "name": "Soil_Grass_Full"
    },
    {
      "x": -11,
      "y": 1,
      "z": -5,
      "name": "Rock_Stone_Cobble"
    },
    {
      "x": -11,
      "y": 2,
      "z": -5,
      "name": "Rock_Stone_Cobble"
    },
    {
      "x": -11,
      "y": 3,
      "z": -5,
      "name": "Rock_Stone_Cobble"
    },
    {
      "x": -11,
      "y": 4,
      "z": -5,
      "name": "Rock_Stone_Cobble"
    },
    {
      "x": -11,
      "y": 5,
      "z": -5,
      "name": "Rock_Stone_Cobble"
    },
    {
      "x": -11,
      "y": 6,
      "z": -5,
      "name": "Rock_Stone_Brick_Wall",
      "rotation": 1
    },
    {
      "x": -11,
      "y": 0,
      "z": -4,
      "name": "Soil_Grass_Full"
    },
    {
      "x": -11,
      "y": 1,
      "z": -4,
      "name": "Soil_Dirt_Dry"
    },
    {
      "x": -11,
      "y": 2,
      "z": -4,
      "name": "Wood_Oak_Trunk",
      "support": 15
    },
    {
      "x": -11,
      "y": 3,
      "z": -4,
      "name": "Wood_Oak_Trunk",
      "support": 15
    },
    {
      "x": -11,
      "y": 4,
      "z": -4,
      "name": "Wood_Oak_Trunk",
      "support": 15
    },
    {
      "x": -11,
      "y": 5,
      "z": -4,
      "name": "Wood_Oak_Trunk",
      "support": 15
    },
    {
      "x": -11,
      "y": 6,
      "z": -4,
      "name": "*Rock_Stone_Brick_Wall_State_Definitions_Corner",
      "rotation": 3
    },
    {
      "x": -11,
      "y": 0,
      "z": -3,
      "name": "Soil_Grass_Full"
    },
    {
      "x": -11,
      "y": 1,
      "z": -3,
      "name": "Soil_Dirt_Dry"
    },
    {
      "x": -11,
      "y": 2,
      "z": -3,
      "name": "Wood_Oak_Branch_Long",
      "support": 15
    },
    {
      "x": -11,
      "y": 3,
      "z": -3,
      "name": "Wood_Oak_Branch_Long",
      "support": 15
    },
    {
      "x": -11,
      "y": 4,
      "z": -3,
      "name": "Wood_Oak_Branch_Long",
      "support": 15
    },
    {
      "x": -11,
      "y": 5,
      "z": -3,
      "name": "Survival_Trap_Spike_Wood_Large"
    },
    {
      "x": -11,
      "y": 0,
      "z": -2,
      "name": "Soil_Grass_Full"
    },
    {
      "x": -11,
      "y": 1,
      "z": -2,
      "name": "Soil_Dirt_Dry"
    },
    {
      "x": -11,
      "y": 2,
      "z": -2,
      "name": "Survival_Trap_Spike_Wood",
      "rotation": 5
    },
    {
      "x": -11,
      "y": 3,
      "z": -2,
      "name": "Survival_Trap_Spike_Wood",
      "rotation": 5
    },
    {
      "x": -11,
      "y": 4,
      "z": -2,
      "name": "Survival_Trap_Spike_Wood",
      "rotation": 5
    },
    {
      "x": -11,
      "y": 5,
      "z": -2,
      "name": "Survival_Trap_Spike_Wood",
      "rotation": 5
    },
    {
      "x": -11,
      "y": 0,
      "z": -1,
      "name": "Soil_Grass_Full"
    },
    {
      "x": -11,
      "y": 1,
      "z": -1,
      "name": "Soil_Dirt_Dry"
    },
    {
      "x": -11,
      "y": 2,
      "z": -1,
      "name": "Wood_Oak_Branch_Long",
      "support": 15
    },
    {
      "x": -11,
      "y": 3,
      "z": -1,
      "name": "Wood_Oak_Branch_Long",
      "support": 15
    },
    {
      "x": -11,
      "y": 4,
      "z": -1,
      "name": "Wood_Oak_Branch_Long",
      "support": 15
    },
    {
      "x": -11,
      "y": 5,
      "z": -1,
      "name": "Survival_Trap_Spike_Wood_Large"
    },
    {
      "x": -11,
      "y": 0,
      "z": 0,
      "name": "Soil_Grass_Full"
    },
    {
      "x": -11,
      "y": 1,
      "z": 0,
      "name": "Soil_Dirt_Dry"
    },
    {
      "x": -11,
      "y": 2,
      "z": 0,
      "name": "Survival_Trap_Spike_Wood",
      "rotation": 5
    },
    {
      "x": -11,
      "y": 3,
      "z": 0,
      "name": "Survival_Trap_Spike_Wood",
      "rotation": 5
    },
    {
      "x": -11,
      "y": 4,
      "z": 0,
      "name": "Survival_Trap_Spike_Wood",
      "rotation": 5
    },
    {
      "x": -11,
      "y": 5,
      "z": 0,
      "name": "Survival_Trap_Spike_Wood",
      "rotation": 5
    },
    {
      "x": -11,
      "y": 0,
      "z": 1,
      "name": "Soil_Grass_Full"
    },
    {
      "x": -11,
      "y": 1,
      "z": 1,
      "name": "Soil_Dirt_Dry"
    },
    {
      "x": -11,
      "y": 2,
      "z": 1,
      "name": "Wood_Oak_Branch_Long",
      "support": 15
    },
    {
      "x": -11,
      "y": 3,
      "z": 1,
      "name": "Wood_Oak_Branch_Long",
      "support": 15
    },
    {
      "x": -11,
      "y": 4,
      "z": 1,
      "name": "Wood_Oak_Branch_Long",
      "support": 15
    },
    {
      "x": -11,
      "y": 5,
      "z": 1,
      "name": "Survival_Trap_Spike_Wood_Large"
    },
    {
      "x": -11,
      "y": 0,
      "z": 2,
      "name": "Soil_Grass_Full"
    },
    {
      "x": -11,
      "y": 1,
      "z": 2,
      "name": "Soil_Dirt_Dry"
    },
    {
      "x": -11,
      "y": 2,
      "z": 2,
      "name": "Survival_Trap_Spike_Wood",
      "rotation": 5
    },
    {
      "x": -11,
      "y": 3,
      "z": 2,
      "name": "Survival_Trap_Spike_Wood",
      "rotation": 5
    },
    {
      "x": -11,
      "y": 4,
      "z": 2,
      "name": "Survival_Trap_Spike_Wood",
      "rotation": 5
    },
    {
      "x": -11,
      "y": 5,
      "z": 2,
      "name": "Survival_Trap_Spike_Wood",
      "rotation": 5
    },
    {
      "x": -11,
      "y": 0,
      "z": 3,
      "name": "Soil_Grass_Full"
    },
    {
      "x": -11,
      "y": 1,
      "z": 3,
      "name": "Soil_Dirt_Dry"
    },
    {
      "x": -11,
      "y": 2,
      "z": 3,
      "name": "Wood_Oak_Branch_Long",
      "support": 15
    },
    {
      "x": -11,
      "y": 3,
      "z": 3,
      "name": "Wood_Oak_Branch_Long",
      "support": 15
    },
    {
      "x": -11,
      "y": 4,
      "z": 3,
      "name": "Wood_Oak_Branch_Long",
      "support": 15
    },
    {
      "x": -11,
      "y": 5,
      "z": 3,
      "name": "Survival_Trap_Spike_Wood_Large"
    },
    {
      "x": -11,
      "y": 0,
      "z": 4,
      "name": "Soil_Grass_Full"
    },
    {
      "x": -11,
      "y": 1,
      "z": 4,
      "name": "Soil_Dirt_Dry"
    },
    {
      "x": -11,
      "y": 2,
      "z": 4,
      "name": "Survival_Trap_Spike_Wood",
      "rotation": 5
    },
    {
      "x": -11,
      "y": 3,
      "z": 4,
      "name": "Survival_Trap_Spike_Wood",
      "rotation": 5
    },
    {
      "x": -11,
      "y": 4,
      "z": 4,
      "name": "Survival_Trap_Spike_Wood",
      "rotation": 5
    },
    {
      "x": -11,
      "y": 5,
      "z": 4,
      "name": "Survival_Trap_Spike_Wood",
      "rotation": 5
    },
    {
      "x": -11,
      "y": 0,
      "z": 5,
      "name": "Soil_Grass_Full"
    },
    {
      "x": -11,
      "y": 1,
      "z": 5,
      "name": "Soil_Dirt_Dry"
    },
    {
      "x": -11,
      "y": 2,
      "z": 5,
      "name": "Wood_Oak_Branch_Long",
      "support": 15
    },
    {
      "x": -11,
      "y": 3,
      "z": 5,
      "name": "Wood_Oak_Branch_Long",
      "support": 15
    },
    {
      "x": -11,
